Workbook

Sheet 표지
B3: SyncGuard AI 시스템 구축
B5: 작업분할구조도 (WBS)
B6: Work Breakdown Structure & Schedule Master
A8: 작업분할구조도
A9: (WBS, Work Breakdown Structure) | B9: 문서번호 | C9: EMP_INT_020
B10: 버전 | C10: v1.1 (착수 킥오프 합의 및 PoC 반영)
B11: 사업기간 | C11: 2026.10.16 ~ 2027.05.31 (약 7.5개월 / 33주)
B12: 발주사 | C12: 주식회사 한빛글로벌 (Hanbit Global Corp.)
B13: 수행사 | C13: 주식회사 엠파시 (협력: ㈜데이터브릿지
B14: 현재공정률 | C14: 전체 계획 1.0% / 실적 1.2% (분석 단계: 계획 10.0% / 실적 12.0%)
B16: 한빛글로벌 SyncGuard AI | C16: 한빛글로벌 SyncGuard AI 시스템 구축
B17: 최종작성일 | C17: 2026. 10. 23. (제1차 주간보고 기준)
B18: 산출물 ID | C18: EMP_INT_020 | E18: 버전 | F18: v1.1
C26: 엠파시 (수행사) | E26: 한빛글로벌
C27: 김태윤 PM | E27: 정민수 PM
C28: (인) | E28: (인)

Sheet 문서이력
A1: 제·개정 이력
A3: 버전 | B3: 개정일 | C3: 개정사유 | D3: 개정내역 | E3: 작성자 | F3: 승인자
A4: v0.9 | B4: 2026-10-15 | C4: 초기 제정 | D4: 사업수행계획서 기준 초기 WBS 및 6대 마일스톤(M1~M6) 초안 수립 | E4: 김태윤 PM | F4: 정민수 PM
A5: v1.0 | B5: 2026-10-16 | C5: 착수 확정 | D5: 10/16 착수 킥오프 회의 합의사항 반영 (마케팅허브 연계, 데이터브릿지 3M 투입, 골든셋 단계적 구축) | E5: 박준혁 AA / 김태윤 PM | F5: 정민수 PM / 한승우 PM
A6: v1.1 | B6: 2026-10-23 | C6: PoC/진척 반영 | D6: 제1차 주간보고 기준 진척률(전체 계획 1.0%/실적 1.2%, 분석 계획 10.0%/실적 12.0%) 및 동영상 캡처·목업 PoC 반영 | E6: 김태윤 PM / 박준혁 AA | F6: 정민수 PM / RA Lab
A19: 개정 사유 제정 또는 개정 내용이 이전 문서에 대해 추가/수정/삭제인지 선택 기입
A20: 개정 내역 개정이 발생하는 페이지 번호와 변경 내용을 기술

Sheet 프로젝트WBS
B1: 한빛글로벌 SyncGuard AI 시스템 구축 작업분할구조도 (WBS) | J1: 실적기준일 : | K1: 46324 | S1: SPI (일정수행지수) | T1: =T5/R5 -> 3.4642857 | U1: =IF(T1<0.75,"(위험)",IF(T1<0.85,"(경고)",IF(T1<0.95,"(주의)","(양호)"))) -> (양호)
V2: =DATE(2026,10,16) -> 46311 | W2: =DATE(2026,10,19) -> 46314 | X2: =DATE(2026,10,26) -> 46321 | Y2: =DATE(2026,11,2) -> 46328 | Z2: =DATE(2026,11,9) -> 46335 | AA2: =DATE(2026,11,16) -> 46342 | AB2: =DATE(2026,11,23) -> 46349 | AC2: =DATE(2026,11,30) -> 46356 | AD2: =DATE(2026,12,7) -> 46363 | AE2: =DATE(2026,12,14) -> 46370 | AF2: =DATE(2026,12,21) -> 46377 | AG2: =DATE(2026,12,28) -> 46384 | AH2: =DATE(2027,1,4) -> 46391 | AI2: =DATE(2027,1,11) -> 46398 | AJ2: =DATE(2027,1,18) -> 46405 | AK2: =DATE(2027,1,25) -> 46412 | AL2: =DATE(2027,2,1) -> 46419 | AM2: =DATE(2027,2,8) -> 46426 | AN2: =DATE(2027,2,15) -> 46433 | AO2: =DATE(2027,2,22) -> 46440 | AP2: =DATE(2027,3,1) -> 46447 | AQ2: =DATE(2027,3,8) -> 46454 | AR2: =DATE(2027,3,15) -> 46461 | AS2: =DATE(2027,3,22) -> 46468 | AT2: =DATE(2027,3,29) -> 46475 | AU2: =DATE(2027,4,5) -> 46482 | AV2: =DATE(2027,4,12) -> 46489 | AW2: =DATE(2027,4,19) -> 46496 | AX2: =DATE(2027,4,26) -> 46503 | AY2: =DATE(2027,5,3) -> 46510 | AZ2: =DATE(2027,5,10) -> 46517 | BA2: =DATE(2027,5,17) -> 46524 | BB2: =DATE(2027,5,24) -> 46531 | BC2: =DATE(2027,6,1) -> 46539
B3: 단계 | F3: TASK | H3: 담당 | J3: 계획 시작일 | K3: 예상 완료일 | L3: 실제 시작일 | M3: 실제 완료(예정)일 | N3: 계획 기간 | O3: 실제 기간 | P3: 계획 진행 | Q3: 실제 진행 | R3: 계획 완료율 | S3: 작업 완료율 | T3: 프로젝트 실적 | V3: 일정 (2026.10 ~ 2027.05)
H4: 담당 | I4: 산출물 | T4: 진척율 | U4: 달성율 | V4: 46296 | Y4: 46327 | AC4: 46357 | AH4: 46388 | AL4: 46419 | AP4: 46447 | AU4: 46478 | AY4: 46508
C5: 가중치 | D5: 수행단계 | J5: =MIN(J6:J36) -> 46311 | K5: =MAX(K6:K36) -> 46538 | L5: =MIN(L6:L36) -> 46311 | M5: =MAX(M6:M36) -> 46346 | N5: =N37 -> 656 | O5: =O37 -> 59 | P5: =P37 -> 28 | Q5: =Q37 -> 28 | R5: {=C6*SUMPRODUCT(R6:R9,{0.1;0.3;0.3;0.3})+C10*IFERROR(AVERAGE(R10:R14),0)+C15*IFERROR(AVERAGE(R15:R27),0)+C28*IFERROR(AVERAGE(R28:R33),0)+C34*IFERROR(AVERAGE(R34:R36),0)} -> 0.0448 | S5: =IFERROR(Q37/O37,0) -> 0.47457627 | T5: {=C6*SUMPRODUCT(T6:T9,{0.1;0.3;0.3;0.3})+C10*IFERROR(AVERAGE(T10:T14),0)+C15*IFERROR(AVERAGE(T15:T27),0)+C28*IFERROR(AVERAGE(T28:T33),0)+C34*IFERROR(AVERAGE(T34:T36),0)} -> 0.1552 | U5: =T5-R5 -> 0.1104 | V5: ="10월 3W"&IF(AND(DATE(2026,10,16)<=IF(ISBLANK($K$1), TODAY(), $K$1), IF(ISBLANK($K$1), TODAY(), $K$1)<DATE(2026,10,19)), "★", "") -> 10월 3W | W5: ="10월 4W"&IF(AND(DATE(2026,10,19)<=IF(ISBLANK($K$1), TODAY(), $K$1), IF(ISBLANK($K$1), TODAY(), $K$1)<DATE(2026,10,26)), "★", "") -> 10월 4W | X5: ="10월 5W"&IF(AND(DATE(2026,10,26)<=IF(ISBLANK($K$1), TODAY(), $K$1), IF(ISBLANK($K$1), TODAY(), $K$1)<DATE(2026,11,2)), "★", "") -> 10월 5W★ | Y5: ="11월 1W"&IF(AND(DATE(2026,11,2)<=IF(ISBLANK($K$1), TODAY(), $K$1), IF(ISBLANK($K$1), TODAY(), $K$1)<DATE(2026,11,9)), "★", "") -> 11월 1W | Z5: ="11월 2W"&IF(AND(DATE(2026,11,9)<=IF(ISBLANK($K$1), TODAY(), $K$1), IF(ISBLANK($K$1), TODAY(), $K$1)<DATE(2026,11,16)), "★", "") -> 11월 2W | AA5: ="11월 3W(M1)"&IF(AND(DATE(2026,11,16)<=IF(ISBLANK($K$1), TODAY(), $K$1), IF(ISBLANK($K$1), TODAY(), $K$1)<DATE(2026,11,23)), "★", "") -> 11월 3W(M1) | AB5: ="11월 4W"&IF(AND(DATE(2026,11,23)<=IF(ISBLANK($K$1), TODAY(), $K$1), IF(ISBLANK($K$1), TODAY(), $K$1)<DATE(2026,11,30)), "★", "") -> 11월 4W | AC5: ="12월 1W"&IF(AND(DATE(2026,11,30)<=IF(ISBLANK($K$1), TODAY(), $K$1), IF(ISBLANK($K$1), TODAY(), $K$1)<DATE(2026,12,7)), "★", "") -> 12월 1W | AD5: ="12월 2W"&IF(AND(DATE(2026,12,7)<=IF(ISBLANK($K$1), TODAY(), $K$1), IF(ISBLANK($K$1), TODAY(), $K$1)<DATE(2026,12,14)), "★", "") -> 12월 2W | AE5: ="12월 3W"&IF(AND(DATE(2026,12,14)<=IF(ISBLANK($K$1), TODAY(), $K$1), IF(ISBLANK($K$1), TODAY(), $K$1)<DATE(2026,12,21)), "★", "") -> 12월 3W | AF5: ="12월 4W"&IF(AND(DATE(2026,12,21)<=IF(ISBLANK($K$1), TODAY(), $K$1), IF(ISBLANK($K$1), TODAY(), $K$1)<DATE(2026,12,28)), "★", "") -> 12월 4W | AG5: ="12월 5W"&IF(AND(DATE(2026,12,28)<=IF(ISBLANK($K$1), TODAY(), $K$1), IF(ISBLANK($K$1), TODAY(), $K$1)<DATE(2027,1,4)), "★", "") -> 12월 5W | AH5: ="1월 1W"&IF(AND(DATE(2027,1,4)<=IF(ISBLANK($K$1), TODAY(), $K$1), IF(ISBLANK($K$1), TODAY(), $K$1)<DATE(2027,1,11)), "★", "") -> 1월 1W | AI5: ="1월 2W"&IF(AND(DATE(2027,1,11)<=IF(ISBLANK($K$1), TODAY(), $K$1), IF(ISBLANK($K$1), TODAY(), $K$1)<DATE(2027,1,18)), "★", "") -> 1월 2W | AJ5: ="1월 3W"&IF(AND(DATE(2027,1,18)<=IF(ISBLANK($K$1), TODAY(), $K$1), IF(ISBLANK($K$1), TODAY(), $K$1)<DATE(2027,1,25)), "★", "") -> 1월 3W | AK5: ="1월 4W(M2/3)"&IF(AND(DATE(2027,1,25)<=IF(ISBLANK($K$1), TODAY(), $K$1), IF(ISBLANK($K$1), TODAY(), $K$1)<DATE(2027,2,1)), "★", "") -> 1월 4W(M2/3) | AL5: ="2월 1W"&IF(AND(DATE(2027,2,1)<=IF(ISBLANK($K$1), TODAY(), $K$1), IF(ISBLANK($K$1), TODAY(), $K$1)<DATE(2027,2,8)), "★", "") -> 2월 1W | AM5: ="2월 2W"&IF(AND(DATE(2027,2,8)<=IF(ISBLANK($K$1), TODAY(), $K$1), IF(ISBLANK($K$1), TODAY(), $K$1)<DATE(2027,2,15)), "★", "") -> 2월 2W | AN5: ="2월 3W"&IF(AND(DATE(2027,2,15)<=IF(ISBLANK($K$1), TODAY(), $K$1), IF(ISBLANK($K$1), TODAY(), $K$1)<DATE(2027,2,22)), "★", "") -> 2월 3W | AO5: ="2월 4W(M4)"&IF(AND(DATE(2027,2,22)<=IF(ISBLANK($K$1), TODAY(), $K$1), IF(ISBLANK($K$1), TODAY(), $K$1)<DATE(2027,3,1)), "★", "") -> 2월 4W(M4) | AP5: ="3월 1W"&IF(AND(DATE(2027,3,1)<=IF(ISBLANK($K$1), TODAY(), $K$1), IF(ISBLANK($K$1), TODAY(), $K$1)<DATE(2027,3,8)), "★", "") -> 3월 1W | AQ5: ="3월 2W"&IF(AND(DATE(2027,3,8)<=IF(ISBLANK($K$1), TODAY(), $K$1), IF(ISBLANK($K$1), TODAY(), $K$1)<DATE(2027,3,15)), "★", "") -> 3월 2W | AR5: ="3월 3W"&IF(AND(DATE(2027,3,15)<=IF(ISBLANK($K$1), TODAY(), $K$1), IF(ISBLANK($K$1), TODAY(), $K$1)<DATE(2027,3,22)), "★", "") -> 3월 3W | AS5: ="3월 4W"&IF(AND(DATE(2027,3,22)<=IF(ISBLANK($K$1), TODAY(), $K$1), IF(ISBLANK($K$1), TODAY(), $K$1)<DATE(2027,3,29)), "★", "") -> 3월 4W | AT5: ="3월 5W"&IF(AND(DATE(2027,3,29)<=IF(ISBLANK($K$1), TODAY(), $K$1), IF(ISBLANK($K$1), TODAY(), $K$1)<DATE(2027,4,5)), "★", "") -> 3월 5W | AU5: ="4월 1W"&IF(AND(DATE(2027,4,5)<=IF(ISBLANK($K$1), TODAY(), $K$1), IF(ISBLANK($K$1), TODAY(), $K$1)<DATE(2027,4,12)), "★", "") -> 4월 1W | AV5: ="4월 2W"&IF(AND(DATE(2027,4,12)<=IF(ISBLANK($K$1), TODAY(), $K$1), IF(ISBLANK($K$1), TODAY(), $K$1)<DATE(2027,4,19)), "★", "") -> 4월 2W | AW5: ="4월 3W"&IF(AND(DATE(2027,4,19)<=IF(ISBLANK($K$1), TODAY(), $K$1), IF(ISBLANK($K$1), TODAY(), $K$1)<DATE(2027,4,26)), "★", "") -> 4월 3W | AX5: ="4월 4W(M5)"&IF(AND(DATE(2027,4,26)<=IF(ISBLANK($K$1), TODAY(), $K$1), IF(ISBLANK($K$1), TODAY(), $K$1)<DATE(2027,5,3)), "★", "") -> 4월 4W(M5) | AY5: ="5월 1W"&IF(AND(DATE(2027,5,3)<=IF(ISBLANK($K$1), TODAY(), $K$1), IF(ISBLANK($K$1), TODAY(), $K$1)<DATE(2027,5,10)), "★", "") -> 5월 1W | AZ5: ="5월 2W"&IF(AND(DATE(2027,5,10)<=IF(ISBLANK($K$1), TODAY(), $K$1), IF(ISBLANK($K$1), TODAY(), $K$1)<DATE(2027,5,17)), "★", "") -> 5월 2W | BA5: ="5월 3W"&IF(AND(DATE(2027,5,17)<=IF(ISBLANK($K$1), TODAY(), $K$1), IF(ISBLANK($K$1), TODAY(), $K$1)<DATE(2027,5,24)), "★", "") -> 5월 3W | BB5: ="5월 4W(M6)"&IF(AND(DATE(2027,5,24)<=IF(ISBLANK($K$1), TODAY(), $K$1), IF(ISBLANK($K$1), TODAY(), $K$1)<=DATE(2027,5,31)), "★", "") -> 5월 4W(M6)
B6: 1 | C6: 0.1 | D6: 분석 및 기획 | E6: [01] 착수 및 요구사항·연계·PoC 정의 | F6: 착수 킥오프(10/16) 및 수행계획·계정/소통채널 개설 | H6: 사업총괄(PM) | I6: 착수회의록(EMP_MAN_020), WBS, 사내계정 | J6: 46311 | K6: 46318 | L6: 46311 | M6: 46318 | N6: =IF(OR(ISBLANK(J6),ISBLANK(K6)),"",NETWORKDAYS(J6,K6,'휴일'!$A$2:$A$13)) -> 6 | O6: =IF(OR(ISBLANK(L6),ISBLANK(M6)),"",IF(NETWORKDAYS(L6,M6,'휴일'!$A$2:$A$13)<0,"",NETWORKDAYS(L6,M6,'휴일'!$A$2:$A$13))) -> 6 | P6: =IFERROR(IF(K6>=$K$1,IF(NETWORKDAYS(J6,$K$1,'휴일'!$A$2:$A$13)>0,NETWORKDAYS(J6,$K$1,'휴일'!$A$2:$A$13),""),NETWORKDAYS(J6,K6,'휴일'!$A$2:$A$13)),"") -> 6 | Q6: =IF(IFERROR(IF(M6>=$K$1,IF(NETWORKDAYS(L6,$K$1,'휴일'!$A$2:$A$13)>0,NETWORKDAYS(L6,$K$1,'휴일'!$A$2:$A$13),""),NETWORKDAYS(L6,M6,'휴일'!$A$2:$A$13)),"")<0,"",IFERROR(IF(M6>=$K$1,IF(NETWORKDAYS(L6,$K$1,'휴일'!$A$2:$A$13)>0,NETWORKDAYS(L6,$K$1,'휴일'!$A$2:$A$13),""),NETWORKDAYS(L6,M6,'휴일'!$A$2:$A$13)),"")) -> 6 | R6: =IFERROR(P6/N6,0) -> 1 | S6: =IFERROR(Q6/O6,0) -> 1 | T6: =IF(OR(ISBLANK(Q6),ISBLANK(N6),Q6<=0,N6<=0),0,IF(Q6="",0,1-(Q6-N6)/N6)) -> 1 | U6: =T6-R6 -> 0 | V6: =IF(ISNUMBER(SEARCH("★M", $I6)), IF(AND(IF($M6<>"", $M6, $K6) >= V$2, IF($M6<>"", $M6, $K6) < W$2), MID($I6, SEARCH("★M", $I6)+1, 2), ""), IF(AND($S6>=1, IF($M6<>"", $M6, $K6) >= V$2, IF($M6<>"", $M6, $K6) < W$2), "완료", "")) | W6: =IF(ISNUMBER(SEARCH("★M", $I6)), IF(AND(IF($M6<>"", $M6, $K6) >= W$2, IF($M6<>"", $M6, $K6) < X$2), MID($I6, SEARCH("★M", $I6)+1, 2), ""), IF(AND($S6>=1, IF($M6<>"", $M6, $K6) >= W$2, IF($M6<>"", $M6, $K6) < X$2), "완료", "")) -> 완료 | X6: =IF(ISNUMBER(SEARCH("★M", $I6)), IF(AND(IF($M6<>"", $M6, $K6) >= X$2, IF($M6<>"", $M6, $K6) < Y$2), MID($I6, SEARCH("★M", $I6)+1, 2), ""), IF(AND($S6>=1, IF($M6<>"", $M6, $K6) >= X$2, IF($M6<>"", $M6, $K6) < Y$2), "완료", "")) | Y6: =IF(ISNUMBER(SEARCH("★M", $I6)), IF(AND(IF($M6<>"", $M6, $K6) >= Y$2, IF($M6<>"", $M6, $K6) < Z$2), MID($I6, SEARCH("★M", $I6)+1, 2), ""), IF(AND($S6>=1, IF($M6<>"", $M6, $K6) >= Y$2, IF($M6<>"", $M6, $K6) < Z$2), "완료", "")) | Z6: =IF(ISNUMBER(SEARCH("★M", $I6)), IF(AND(IF($M6<>"", $M6, $K6) >= Z$2, IF($M6<>"", $M6, $K6) < AA$2), MID($I6, SEARCH("★M", $I6)+1, 2), ""), IF(AND($S6>=1, IF($M6<>"", $M6, $K6) >= Z$2, IF($M6<>"", $M6, $K6) < AA$2), "완료", "")) | AA6: =IF(ISNUMBER(SEARCH("★M", $I6)), IF(AND(IF($M6<>"", $M6, $K6) >= AA$2, IF($M6<>"", $M6, $K6) < AB$2), MID($I6, SEARCH("★M", $I6)+1, 2), ""), IF(AND($S6>=1, IF($M6<>"", $M6, $K6) >= AA$2, IF($M6<>"", $M6, $K6) < AB$2), "완료", "")) | AB6: =IF(ISNUMBER(SEARCH("★M", $I6)), IF(AND(IF($M6<>"", $M6, $K6) >= AB$2, IF($M6<>"", $M6, $K6) < AC$2), MID($I6, SEARCH("★M", $I6)+1, 2), ""), IF(AND($S6>=1, IF($M6<>"", $M6, $K6) >= AB$2, IF($M6<>"", $M6, $K6) < AC$2), "완료", "")) | AC6: =IF(ISNUMBER(SEARCH("★M", $I6)), IF(AND(IF($M6<>"", $M6, $K6) >= AC$2, IF($M6<>"", $M6, $K6) < AD$2), MID($I6, SEARCH("★M", $I6)+1, 2), ""), IF(AND($S6>=1, IF($M6<>"", $M6, $K6) >= AC$2, IF($M6<>"", $M6, $K6) < AD$2), "완료", "")) | ... BB6: =IF(ISNUMBER(SEARCH("★M", $I6)), IF(AND(IF($M6<>"", $M6, $K6) >= BB$2, IF($M6<>"", $M6, $K6) < BC$2), MID($I6, SEARCH("★M", $I6)+1, 2), ""), IF(AND($S6>=1, IF($M6<>"", $M6, $K6) >= BB$2, IF($M6<>"", $M6, $K6) < BC$2), "완료", ""))
F7: 현행 심의 절차 인터뷰(RA 4인 전원) 및 기준자료 정제 | H7: AI 아키텍트 / RA 4인 | I7: 사내 기준 단일포맷 정제본, 인터뷰록 | J7: 46314 | K7: 46346 | L7: 46314 | M7: 46345 | N7: =IF(OR(ISBLANK(J7),ISBLANK(K7)),"",NETWORKDAYS(J7,K7,'휴일'!$A$2:$A$13)) -> 25 | O7: =IF(OR(ISBLANK(L7),ISBLANK(M7)),"",IF(NETWORKDAYS(L7,M7,'휴일'!$A$2:$A$13)<0,"",NETWORKDAYS(L7,M7,'휴일'!$A$2:$A$13))) -> 24 | P7: =IFERROR(IF(K7>=$K$1,IF(NETWORKDAYS(J7,$K$1,'휴일'!$A$2:$A$13)>0,NETWORKDAYS(J7,$K$1,'휴일'!$A$2:$A$13),""),NETWORKDAYS(J7,K7,'휴일'!$A$2:$A$13)),"") -> 9 | Q7: =IF(IFERROR(IF(M7>=$K$1,IF(NETWORKDAYS(L7,$K$1,'휴일'!$A$2:$A$13)>0,NETWORKDAYS(L7,$K$1,'휴일'!$A$2:$A$13),""),NETWORKDAYS(L7,M7,'휴일'!$A$2:$A$13)),"")<0,"",IFERROR(IF(M7>=$K$1,IF(NETWORKDAYS(L7,$K$1,'휴일'!$A$2:$A$13)>0,NETWORKDAYS(L7,$K$1,'휴일'!$A$2:$A$13),""),NETWORKDAYS(L7,M7,'휴일'!$A$2:$A$13)),"")) -> 9 | R7: =IFERROR(P7/N7,0) -> 0.36 | S7: =IFERROR(Q7/O7,0) -> 0.375 | T7: =IF(OR(ISBLANK(Q7),ISBLANK(N7),Q7<=0,N7<=0),0,IF(Q7="",0,1-(Q7-N7)/N7)) -> 1.64 | U7: =T7-R7 -> 1.28 | V7: =IF(ISNUMBER(SEARCH("★M", $I7)), IF(AND(IF($M7<>"", $M7, $K7) >= V$2, IF($M7<>"", $M7, $K7) < W$2), MID($I7, SEARCH("★M", $I7)+1, 2), ""), IF(AND($S7>=1, IF($M7<>"", $M7, $K7) >= V$2, IF($M7<>"", $M7, $K7) < W$2), "완료", "")) | W7: =IF(ISNUMBER(SEARCH("★M", $I7)), IF(AND(IF($M7<>"", $M7, $K7) >= W$2, IF($M7<>"", $M7, $K7) < X$2), MID($I7, SEARCH("★M", $I7)+1, 2), ""), IF(AND($S7>=1, IF($M7<>"", $M7, $K7) >= W$2, IF($M7<>"", $M7, $K7) < X$2), "완료", "")) | X7: =IF(ISNUMBER(SEARCH("★M", $I7)), IF(AND(IF($M7<>"", $M7, $K7) >= X$2, IF($M7<>"", $M7, $K7) < Y$2), MID($I7, SEARCH("★M", $I7)+1, 2), ""), IF(AND($S7>=1, IF($M7<>"", $M7, $K7) >= X$2, IF($M7<>"", $M7, $K7) < Y$2), "완료", "")) | Y7: =IF(ISNUMBER(SEARCH("★M", $I7)), IF(AND(IF($M7<>"", $M7, $K7) >= Y$2, IF($M7<>"", $M7, $K7) < Z$2), MID($I7, SEARCH("★M", $I7)+1, 2), ""), IF(AND($S7>=1, IF($M7<>"", $M7, $K7) >= Y$2, IF($M7<>"", $M7, $K7) < Z$2), "완료", "")) | Z7: =IF(ISNUMBER(SEARCH("★M", $I7)), IF(AND(IF($M7<>"", $M7, $K7) >= Z$2, IF($M7<>"", $M7, $K7) < AA$2), MID($I7, SEARCH("★M", $I7)+1, 2), ""), IF(AND($S7>=1, IF($M7<>"", $M7, $K7) >= Z$2, IF($M7<>"", $M7, $K7) < AA$2), "완료", "")) | AA7: =IF(ISNUMBER(SEARCH("★M", $I7)), IF(AND(IF($M7<>"", $M7, $K7) >= AA$2, IF($M7<>"", $M7, $K7) < AB$2), MID($I7, SEARCH("★M", $I7)+1, 2), ""), IF(AND($S7>=1, IF($M7<>"", $M7, $K7) >= AA$2, IF($M7<>"", $M7, $K7) < AB$2), "완료", "")) | AB7: =IF(ISNUMBER(SEARCH("★M", $I7)), IF(AND(IF($M7<>"", $M7, $K7) >= AB$2, IF($M7<>"", $M7, $K7) < AC$2), MID($I7, SEARCH("★M", $I7)+1, 2), ""), IF(AND($S7>=1, IF($M7<>"", $M7, $K7) >= AB$2, IF($M7<>"", $M7, $K7) < AC$2), "완료", "")) | AC7: =IF(ISNUMBER(SEARCH("★M", $I7)), IF(AND(IF($M7<>"", $M7, $K7) >= AC$2, IF($M7<>"", $M7, $K7) < AD$2), MID($I7, SEARCH("★M", $I7)+1, 2), ""), IF(AND($S7>=1, IF($M7<>"", $M7, $K7) >= AC$2, IF($M7<>"", $M7, $K7) < AD$2), "완료", "")) | ... BB7: =IF(ISNUMBER(SEARCH("★M", $I7)), IF(AND(IF($M7<>"", $M7, $K7) >= BB$2, IF($M7<>"", $M7, $K7) < BC$2), MID($I7, SEARCH("★M", $I7)+1, 2), ""), IF(AND($S7>=1, IF($M7<>"", $M7, $K7) >= BB$2, IF($M7<>"", $M7, $K7) < BC$2), "완료", ""))
F8: 동영상(사용자 지정 장면 캡처), 긴 JPG PoC 및 목업 검증 | H8: 박준혁 AA / 데이터브릿지 | I8: 동영상 장면캡처 PoC, 마케팅허브·프로덕트랩 목업 | J8: 46314 | K8: 46332 | L8: 46314 | M8: 46324 | N8: =IF(OR(ISBLANK(J8),ISBLANK(K8)),"",NETWORKDAYS(J8,K8,'휴일'!$A$2:$A$13)) -> 15 | O8: =IF(OR(ISBLANK(L8),ISBLANK(M8)),"",IF(NETWORKDAYS(L8,M8,'휴일'!$A$2:$A$13)<0,"",NETWORKDAYS(L8,M8,'휴일'!$A$2:$A$13))) -> 9 | P8: =IFERROR(IF(K8>=$K$1,IF(NETWORKDAYS(J8,$K$1,'휴일'!$A$2:$A$13)>0,NETWORKDAYS(J8,$K$1,'휴일'!$A$2:$A$13),""),NETWORKDAYS(J8,K8,'휴일'!$A$2:$A$13)),"") -> 9 | Q8: =IF(IFERROR(IF(M8>=$K$1,IF(NETWORKDAYS(L8,$K$1,'휴일'!$A$2:$A$13)>0,NETWORKDAYS(L8,$K$1,'휴일'!$A$2:$A$13),""),NETWORKDAYS(L8,M8,#REF!)),"")<0,"",IFERROR(IF(M8>=$K$1,IF(NETWORKDAYS(L8,$K$1,'휴일'!$A$2:$A$13)>0,NETWORKDAYS(L8,$K$1,'휴일'!$A$2:$A$13),""),NETWORKDAYS(L8,M8,#REF!)),"")) -> 9 | R8: =IFERROR(P8/N8,0) -> 0.6 | S8: =IFERROR(Q8/O8,0) -> 1 | T8: =IF(OR(ISBLANK(Q8),ISBLANK(N8),Q8<=0,N8<=0),0,IF(Q8="",0,1-(Q8-N8)/N8)) -> 1.4 | U8: =T8-R8 -> 0.8 | V8: =IF(ISNUMBER(SEARCH("★M", $I8)), IF(AND(IF($M8<>"", $M8, $K8) >= V$2, IF($M8<>"", $M8, $K8) < W$2), MID($I8, SEARCH("★M", $I8)+1, 2), ""), IF(AND($S8>=1, IF($M8<>"", $M8, $K8) >= V$2, IF($M8<>"", $M8, $K8) < W$2), "완료", "")) | W8: =IF(ISNUMBER(SEARCH("★M", $I8)), IF(AND(IF($M8<>"", $M8, $K8) >= W$2, IF($M8<>"", $M8, $K8) < X$2), MID($I8, SEARCH("★M", $I8)+1, 2), ""), IF(AND($S8>=1, IF($M8<>"", $M8, $K8) >= W$2, IF($M8<>"", $M8, $K8) < X$2), "완료", "")) | X8: =IF(ISNUMBER(SEARCH("★M", $I8)), IF(AND(IF($M8<>"", $M8, $K8) >= X$2, IF($M8<>"", $M8, $K8) < Y$2), MID($I8, SEARCH("★M", $I8)+1, 2), ""), IF(AND($S8>=1, IF($M8<>"", $M8, $K8) >= X$2, IF($M8<>"", $M8, $K8) < Y$2), "완료", "")) -> 완료 | Y8: =IF(ISNUMBER(SEARCH("★M", $I8)), IF(AND(IF($M8<>"", $M8, $K8) >= Y$2, IF($M8<>"", $M8, $K8) < Z$2), MID($I8, SEARCH("★M", $I8)+1, 2), ""), IF(AND($S8>=1, IF($M8<>"", $M8, $K8) >= Y$2, IF($M8<>"", $M8, $K8) < Z$2), "완료", "")) | Z8: =IF(ISNUMBER(SEARCH("★M", $I8)), IF(AND(IF($M8<>"", $M8, $K8) >= Z$2, IF($M8<>"", $M8, $K8) < AA$2), MID($I8, SEARCH("★M", $I8)+1, 2), ""), IF(AND($S8>=1, IF($M8<>"", $M8, $K8) >= Z$2, IF($M8<>"", $M8, $K8) < AA$2), "완료", "")) | AA8: =IF(ISNUMBER(SEARCH("★M", $I8)), IF(AND(IF($M8<>"", $M8, $K8) >= AA$2, IF($M8<>"", $M8, $K8) < AB$2), MID($I8, SEARCH("★M", $I8)+1, 2), ""), IF(AND($S8>=1, IF($M8<>"", $M8, $K8) >= AA$2, IF($M8<>"", $M8, $K8) < AB$2), "완료", "")) | AB8: =IF(ISNUMBER(SEARCH("★M", $I8)), IF(AND(IF($M8<>"", $M8, $K8) >= AB$2, IF($M8<>"", $M8, $K8) < AC$2), MID($I8, SEARCH("★M", $I8)+1, 2), ""), IF(AND($S8>=1, IF($M8<>"", $M8, $K8) >= AB$2, IF($M8<>"", $M8, $K8) < AC$2), "완료", "")) | AC8: =IF(ISNUMBER(SEARCH("★M", $I8)), IF(AND(IF($M8<>"", $M8, $K8) >= AC$2, IF($M8<>"", $M8, $K8) < AD$2), MID($I8, SEARCH("★M", $I8)+1, 2), ""), IF(AND($S8>=1, IF($M8<>"", $M8, $K8) >= AC$2, IF($M8<>"", $M8, $K8) < AD$2), "완료", "")) | ... BB8: =IF(ISNUMBER(SEARCH("★M", $I8)), IF(AND(IF($M8<>"", $M8, $K8) >= BB$2, IF($M8<>"", $M8, $K8) < BC$2), MID($I8, SEARCH("★M", $I8)+1, 2), ""), IF(AND($S8>=1, IF($M8<>"", $M8, $K8) >= BB$2, IF($M8<>"", $M8, $K8) < BC$2), "완료", ""))
F9: KT레몬 vs 상용 LLM(Claude) 보고서 파싱 비교 및 요구사항 확정 | H9: 사업총괄(PM) / 박준혁 AA | I9: 요구사항정의서(EMP_ANL_020), 연계규격협의서 | J9: 46321 | K9: 46346 | L9: 46321 | M9: 46346 | N9: =IF(OR(ISBLANK(J9),ISBLANK(K9)),"",NETWORKDAYS(J9,K9,'휴일'!$A$2:$A$13)) -> 20 | O9: =IF(OR(ISBLANK(L9),ISBLANK(M9)),"",IF(NETWORKDAYS(L9,M9,'휴일'!$A$2:$A$13)<0,"",NETWORKDAYS(L9,M9,'휴일'!$A$2:$A$13))) -> 20 | P9: =IFERROR(IF(K9>=$K$1,IF(NETWORKDAYS(J9,$K$1,'휴일'!$A$2:$A$13)>0,NETWORKDAYS(J9,$K$1,'휴일'!$A$2:$A$13),""),NETWORKDAYS(J9,K9,'휴일'!$A$2:$A$13)),"") -> 4 | Q9: =IF(IFERROR(IF(M9>=$K$1,IF(NETWORKDAYS(L9,$K$1,'휴일'!$A$2:$A$13)>0,NETWORKDAYS(L9,$K$1,'휴일'!$A$2:$A$13),""),NETWORKDAYS(L9,M9,'휴일'!$A$2:$A$13)),"")<0,"",IFERROR(IF(M9>=$K$1,IF(NETWORKDAYS(L9,$K$1,'휴일'!$A$2:$A$13)>0,NETWORKDAYS(L9,$K$1,'휴일'!$A$2:$A$13),""),NETWORKDAYS(L9,M9,'휴일'!$A$2:$A$13)),"")) -> 4 | R9: =IFERROR(P9/N9,0) -> 0.2 | S9: =IFERROR(Q9/O9,0) -> 0.2 | T9: =IF(OR(ISBLANK(Q9),ISBLANK(N9),Q9<=0,N9<=0),0,IF(Q9="",0,1-(Q9-N9)/N9)) -> 1.8 | U9: =T9-R9 -> 1.6 | V9: =IF(ISNUMBER(SEARCH("★M", $I9)), IF(AND(IF($M9<>"", $M9, $K9) >= V$2, IF($M9<>"", $M9, $K9) < W$2), MID($I9, SEARCH("★M", $I9)+1, 2), ""), IF(AND($S9>=1, IF($M9<>"", $M9, $K9) >= V$2, IF($M9<>"", $M9, $K9) < W$2), "완료", "")) | W9: =IF(ISNUMBER(SEARCH("★M", $I9)), IF(AND(IF($M9<>"", $M9, $K9) >= W$2, IF($M9<>"", $M9, $K9) < X$2), MID($I9, SEARCH("★M", $I9)+1, 2), ""), IF(AND($S9>=1, IF($M9<>"", $M9, $K9) >= W$2, IF($M9<>"", $M9, $K9) < X$2), "완료", "")) | X9: =IF(ISNUMBER(SEARCH("★M", $I9)), IF(AND(IF($M9<>"", $M9, $K9) >= X$2, IF($M9<>"", $M9, $K9) < Y$2), MID($I9, SEARCH("★M", $I9)+1, 2), ""), IF(AND($S9>=1, IF($M9<>"", $M9, $K9) >= X$2, IF($M9<>"", $M9, $K9) < Y$2), "완료", "")) | Y9: =IF(ISNUMBER(SEARCH("★M", $I9)), IF(AND(IF($M9<>"", $M9, $K9) >= Y$2, IF($M9<>"", $M9, $K9) < Z$2), MID($I9, SEARCH("★M", $I9)+1, 2), ""), IF(AND($S9>=1, IF($M9<>"", $M9, $K9) >= Y$2, IF($M9<>"", $M9, $K9) < Z$2), "완료", "")) | Z9: =IF(ISNUMBER(SEARCH("★M", $I9)), IF(AND(IF($M9<>"", $M9, $K9) >= Z$2, IF($M9<>"", $M9, $K9) < AA$2), MID($I9, SEARCH("★M", $I9)+1, 2), ""), IF(AND($S9>=1, IF($M9<>"", $M9, $K9) >= Z$2, IF($M9<>"", $M9, $K9) < AA$2), "완료", "")) | AA9: =IF(ISNUMBER(SEARCH("★M", $I9)), IF(AND(IF($M9<>"", $M9, $K9) >= AA$2, IF($M9<>"", $M9, $K9) < AB$2), MID($I9, SEARCH("★M", $I9)+1, 2), ""), IF(AND($S9>=1, IF($M9<>"", $M9, $K9) >= AA$2, IF($M9<>"", $M9, $K9) < AB$2), "완료", "")) | AB9: =IF(ISNUMBER(SEARCH("★M", $I9)), IF(AND(IF($M9<>"", $M9, $K9) >= AB$2, IF($M9<>"", $M9, $K9) < AC$2), MID($I9, SEARCH("★M", $I9)+1, 2), ""), IF(AND($S9>=1, IF($M9<>"", $M9, $K9) >= AB$2, IF($M9<>"", $M9, $K9) < AC$2), "완료", "")) | AC9: =IF(ISNUMBER(SEARCH("★M", $I9)), IF(AND(IF($M9<>"", $M9, $K9) >= AC$2, IF($M9<>"", $M9, $K9) < AD$2), MID($I9, SEARCH("★M", $I9)+1, 2), ""), IF(AND($S9>=1, IF($M9<>"", $M9, $K9) >= AC$2, IF($M9<>"", $M9, $K9) < AD$2), "완료", "")) | ... BB9: =IF(ISNUMBER(SEARCH("★M", $I9)), IF(AND(IF($M9<>"", $M9, $K9) >= BB$2, IF($M9<>"", $M9, $K9) < BC$2), MID($I9, SEARCH("★M", $I9)+1, 2), ""), IF(AND($S9>=1, IF($M9<>"", $M9, $K9) >= BB$2, IF($M9<>"", $M9, $K9) < BC$2), "완료", ""))
B10: 2 | C10: 0.15 | D10: 상세 설계 | E10: [02] 화면·DB·IA·연계 상세 설계 | F10: 마케팅허브 중심 의뢰/결과 동선 및 Side-by-Side 대조 뷰어 설계 | H10: 프론트엔드 개발자 | I10: 화면설계서(대조뷰어·동영상캡처·관리자웹) | J10: 46328 | K10: 46346 | N10: =IF(OR(ISBLANK(J10),ISBLANK(K10)),"",NETWORKDAYS(J10,K10,'휴일'!$A$2:$A$13)) -> 15 | O10: =IF(OR(ISBLANK(L10),ISBLANK(M10)),"",IF(NETWORKDAYS(L10,M10,'휴일'!$A$2:$A$13)<0,"",NETWORKDAYS(L10,M10,'휴일'!$A$2:$A$13))) | P10: =IFERROR(IF(K10>=$K$1,IF(NETWORKDAYS(J10,$K$1,'휴일'!$A$2:$A$13)>0,NETWORKDAYS(J10,$K$1,'휴일'!$A$2:$A$13),""),NETWORKDAYS(J10,K10,'휴일'!$A$2:$A$13)),"") | Q10: =IF(IFERROR(IF(M10>=$K$1,IF(NETWORKDAYS(L10,$K$1,'휴일'!$A$2:$A$13)>0,NETWORKDAYS(L10,$K$1,'휴일'!$A$2:$A$13),""),NETWORKDAYS(L10,M10,'휴일'!$A$2:$A$13)),"")<0,"",IFERROR(IF(M10>=$K$1,IF(NETWORKDAYS(L10,$K$1,'휴일'!$A$2:$A$13)>0,NETWORKDAYS(L10,$K$1,'휴일'!$A$2:$A$13),""),NETWORKDAYS(L10,M10,'휴일'!$A$2:$A$13)),"")) -> 0 | R10: =IFERROR(P10/N10,0) -> 0 | S10: =IFERROR(Q10/O10,0) -> 0 | T10: =IF(OR(ISBLANK(Q10),ISBLANK(N10),Q10<=0,N10<=0),0,IF(Q10="",0,1-(Q10-N10)/N10)) -> 0 | U10: =T10-R10 -> 0 | V10: =IF(ISNUMBER(SEARCH("★M", $I10)), IF(AND(IF($M10<>"", $M10, $K10) >= V$2, IF($M10<>"", $M10, $K10) < W$2), MID($I10, SEARCH("★M", $I10)+1, 2), ""), IF(AND($S10>=1, IF($M10<>"", $M10, $K10) >= V$2, IF($M10<>"", $M10, $K10) < W$2), "완료", "")) | W10: =IF(ISNUMBER(SEARCH("★M", $I10)), IF(AND(IF($M10<>"", $M10, $K10) >= W$2, IF($M10<>"", $M10, $K10) < X$2), MID($I10, SEARCH("★M", $I10)+1, 2), ""), IF(AND($S10>=1, IF($M10<>"", $M10, $K10) >= W$2, IF($M10<>"", $M10, $K10) < X$2), "완료", "")) | X10: =IF(ISNUMBER(SEARCH("★M", $I10)), IF(AND(IF($M10<>"", $M10, $K10) >= X$2, IF($M10<>"", $M10, $K10) < Y$2), MID($I10, SEARCH("★M", $I10)+1, 2), ""), IF(AND($S10>=1, IF($M10<>"", $M10, $K10) >= X$2, IF($M10<>"", $M10, $K10) < Y$2), "완료", "")) | Y10: =IF(ISNUMBER(SEARCH("★M", $I10)), IF(AND(IF($M10<>"", $M10, $K10) >= Y$2, IF($M10<>"", $M10, $K10) < Z$2), MID($I10, SEARCH("★M", $I10)+1, 2), ""), IF(AND($S10>=1, IF($M10<>"", $M10, $K10) >= Y$2, IF($M10<>"", $M10, $K10) < Z$2), "완료", "")) | Z10: =IF(ISNUMBER(SEARCH("★M", $I10)), IF(AND(IF($M10<>"", $M10, $K10) >= Z$2, IF($M10<>"", $M10, $K10) < AA$2), MID($I10, SEARCH("★M", $I10)+1, 2), ""), IF(AND($S10>=1, IF($M10<>"", $M10, $K10) >= Z$2, IF($M10<>"", $M10, $K10) < AA$2), "완료", "")) | AA10: =IF(ISNUMBER(SEARCH("★M", $I10)), IF(AND(IF($M10<>"", $M10, $K10) >= AA$2, IF($M10<>"", $M10, $K10) < AB$2), MID($I10, SEARCH("★M", $I10)+1, 2), ""), IF(AND($S10>=1, IF($M10<>"", $M10, $K10) >= AA$2, IF($M10<>"", $M10, $K10) < AB$2), "완료", "")) | AB10: =IF(ISNUMBER(SEARCH("★M", $I10)), IF(AND(IF($M10<>"", $M10, $K10) >= AB$2, IF($M10<>"", $M10, $K10) < AC$2), MID($I10, SEARCH("★M", $I10)+1, 2), ""), IF(AND($S10>=1, IF($M10<>"", $M10, $K10) >= AB$2, IF($M10<>"", $M10, $K10) < AC$2), "완료", "")) | AC10: =IF(ISNUMBER(SEARCH("★M", $I10)), IF(AND(IF($M10<>"", $M10, $K10) >= AC$2, IF($M10<>"", $M10, $K10) < AD$2), MID($I10, SEARCH("★M", $I10)+1, 2), ""), IF(AND($S10>=1, IF($M10<>"", $M10, $K10) >= AC$2, IF($M10<>"", $M10, $K10) < AD$2), "완료", "")) | ... BB10: =IF(ISNUMBER(SEARCH("★M", $I10)), IF(AND(IF($M10<>"", $M10, $K10) >= BB$2, IF($M10<>"", $M10, $K10) < BC$2), MID($I10, SEARCH("★M", $I10)+1, 2), ""), IF(AND($S10>=1, IF($M10<>"", $M10, $K10) >= BB$2, IF($M10<>"", $M10, $K10) < BC$2), "완료", ""))
F11: PostgreSQL 16 + pgvector 통합 스키마 및 실증 DB ERD 설계 | H11: 백엔드 / 데이터브릿지 | I11: 데이터베이스명세서, ERD (마케팅허브 RDB·ProductLab) | J11: 46328 | K11: 46346 | N11: =IF(OR(ISBLANK(J11),ISBLANK(K11)),"",NETWORKDAYS(J11,K11,'휴일'!$A$2:$A$13)) -> 15 | O11: =IF(OR(ISBLANK(L11),ISBLANK(M11)),"",IF(NETWORKDAYS(L11,M11,'휴일'!$A$2:$A$13)<0,"",NETWORKDAYS(L11,M11,'휴일'!$A$2:$A$13))) | P11: =IFERROR(IF(K11>=$K$1,IF(NETWORKDAYS(J11,$K$1,'휴일'!$A$2:$A$13)>0,NETWORKDAYS(J11,$K$1,'휴일'!$A$2:$A$13),""),NETWORKDAYS(J11,K11,'휴일'!$A$2:$A$13)),"") | Q11: =IF(IFERROR(IF(M11>=$K$1,IF(NETWORKDAYS(L11,$K$1,'휴일'!$A$2:$A$13)>0,NETWORKDAYS(L11,$K$1,'휴일'!$A$2:$A$13),""),NETWORKDAYS(L11,M11,'휴일'!$A$2:$A$13)),"")<0,"",IFERROR(IF(M11>=$K$1,IF(NETWORKDAYS(L11,$K$1,'휴일'!$A$2:$A$13)>0,NETWORKDAYS(L11,$K$1,'휴일'!$A$2:$A$13),""),NETWORKDAYS(L11,M11,'휴일'!$A$2:$A$13)),"")) -> 0 | R11: =IFERROR(P11/N11,0) -> 0 | S11: =IFERROR(Q11/O11,0) -> 0 | T11: =IF(OR(ISBLANK(Q11),ISBLANK(N11),Q11<=0,N11<=0),0,IF(Q11="",0,1-(Q11-N11)/N11)) -> 0 | U11: =T11-R11 -> 0 | V11: =IF(ISNUMBER(SEARCH("★M", $I11)), IF(AND(IF($M11<>"", $M11, $K11) >= V$2, IF($M11<>"", $M11, $K11) < W$2), MID($I11, SEARCH("★M", $I11)+1, 2), ""), IF(AND($S11>=1, IF($M11<>"", $M11, $K11) >= V$2, IF($M11<>"", $M11, $K11) < W$2), "완료", "")) | W11: =IF(ISNUMBER(SEARCH("★M", $I11)), IF(AND(IF($M11<>"", $M11, $K11) >= W$2, IF($M11<>"", $M11, $K11) < X$2), MID($I11, SEARCH("★M", $I11)+1, 2), ""), IF(AND($S11>=1, IF($M11<>"", $M11, $K11) >= W$2, IF($M11<>"", $M11, $K11) < X$2), "완료", "")) | X11: =IF(ISNUMBER(SEARCH("★M", $I11)), IF(AND(IF($M11<>"", $M11, $K11) >= X$2, IF($M11<>"", $M11, $K11) < Y$2), MID($I11, SEARCH("★M", $I11)+1, 2), ""), IF(AND($S11>=1, IF($M11<>"", $M11, $K11) >= X$2, IF($M11<>"", $M11, $K11) < Y$2), "완료", "")) | Y11: =IF(ISNUMBER(SEARCH("★M", $I11)), IF(AND(IF($M11<>"", $M11, $K11) >= Y$2, IF($M11<>"", $M11, $K11) < Z$2), MID($I11, SEARCH("★M", $I11)+1, 2), ""), IF(AND($S11>=1, IF($M11<>"", $M11, $K11) >= Y$2, IF($M11<>"", $M11, $K11) < Z$2), "완료", "")) | Z11: =IF(ISNUMBER(SEARCH("★M", $I11)), IF(AND(IF($M11<>"", $M11, $K11) >= Z$2, IF($M11<>"", $M11, $K11) < AA$2), MID($I11, SEARCH("★M", $I11)+1, 2), ""), IF(AND($S11>=1, IF($M11<>"", $M11, $K11) >= Z$2, IF($M11<>"", $M11, $K11) < AA$2), "완료", "")) | AA11: =IF(ISNUMBER(SEARCH("★M", $I11)), IF(AND(IF($M11<>"", $M11, $K11) >= AA$2, IF($M11<>"", $M11, $K11) < AB$2), MID($I11, SEARCH("★M", $I11)+1, 2), ""), IF(AND($S11>=1, IF($M11<>"", $M11, $K11) >= AA$2, IF($M11<>"", $M11, $K11) < AB$2), "완료", "")) | AB11: =IF(ISNUMBER(SEARCH("★M", $I11)), IF(AND(IF($M11<>"", $M11, $K11) >= AB$2, IF($M11<>"", $M11, $K11) < AC$2), MID($I11, SEARCH("★M", $I11)+1, 2), ""), IF(AND($S11>=1, IF($M11<>"", $M11, $K11) >= AB$2, IF($M11<>"", $M11, $K11) < AC$2), "완료", "")) | AC11: =IF(ISNUMBER(SEARCH("★M", $I11)), IF(AND(IF($M11<>"", $M11, $K11) >= AC$2, IF($M11<>"", $M11, $K11) < AD$2), MID($I11, SEARCH("★M", $I11)+1, 2), ""), IF(AND($S11>=1, IF($M11<>"", $M11, $K11) >= AC$2, IF($M11<>"", $M11, $K11) < AD$2), "완료", "")) | ... BB11: =IF(ISNUMBER(SEARCH("★M", $I11)), IF(AND(IF($M11<>"", $M11, $K11) >= BB$2, IF($M11<>"", $M11, $K11) < BC$2), MID($I11, SEARCH("★M", $I11)+1, 2), ""), IF(AND($S11>=1, IF($M11<>"", $M11, $K11) >= BB$2, IF($M11<>"", $M11, $K11) < BC$2), "완료", ""))
F12: 마케팅허브 REST API·뷰어 링크, ProductLab 배치, HB-SSO IAM 설계 | H12: 백엔드 / 데이터브릿지 | I12: 인터페이스설계서, 배치설계서 (데이터브릿지 11월 투입) | J12: 46335 | K12: 46360 | N12: =IF(OR(ISBLANK(J12),ISBLANK(K12)),"",NETWORKDAYS(J12,K12,'휴일'!$A$2:$A$13)) -> 20 | O12: =IF(OR(ISBLANK(L12),ISBLANK(M12)),"",IF(NETWORKDAYS(L12,M12,'휴일'!$A$2:$A$13)<0,"",NETWORKDAYS(L12,M12,'휴일'!$A$2:$A$13))) | P12: =IFERROR(IF(K12>=$K$1,IF(NETWORKDAYS(J12,$K$1,'휴일'!$A$2:$A$13)>0,NETWORKDAYS(J12,$K$1,'휴일'!$A$2:$A$13),""),NETWORKDAYS(J12,K12,'휴일'!$A$2:$A$13)),"") | Q12: =IF(IFERROR(IF(M12>=$K$1,IF(NETWORKDAYS(L12,$K$1,'휴일'!$A$2:$A$13)>0,NETWORKDAYS(L12,$K$1,'휴일'!$A$2:$A$13),""),NETWORKDAYS(L12,M12,'휴일'!$A$2:$A$13)),"")<0,"",IFERROR(IF(M12>=$K$1,IF(NETWORKDAYS(L12,$K$1,'휴일'!$A$2:$A$13)>0,NETWORKDAYS(L12,$K$1,'휴일'!$A$2:$A$13),""),NETWORKDAYS(L12,M12,'휴일'!$A$2:$A$13)),"")) -> 0 | R12: =IFERROR(P12/N12,0) -> 0 | S12: =IFERROR(Q12/O12,0) -> 0 | T12: =IF(OR(ISBLANK(Q12),ISBLANK(N12),Q12<=0,N12<=0),0,IF(Q12="",0,1-(Q12-N12)/N12)) -> 0 | U12: =T12-R12 -> 0 | V12: =IF(ISNUMBER(SEARCH("★M", $I12)), IF(AND(IF($M12<>"", $M12, $K12) >= V$2, IF($M12<>"", $M12, $K12) < W$2), MID($I12, SEARCH("★M", $I12)+1, 2), ""), IF(AND($S12>=1, IF($M12<>"", $M12, $K12) >= V$2, IF($M12<>"", $M12, $K12) < W$2), "완료", "")) | W12: =IF(ISNUMBER(SEARCH("★M", $I12)), IF(AND(IF($M12<>"", $M12, $K12) >= W$2, IF($M12<>"", $M12, $K12) < X$2), MID($I12, SEARCH("★M", $I12)+1, 2), ""), IF(AND($S12>=1, IF($M12<>"", $M12, $K12) >= W$2, IF($M12<>"", $M12, $K12) < X$2), "완료", "")) | X12: =IF(ISNUMBER(SEARCH("★M", $I12)), IF(AND(IF($M12<>"", $M12, $K12) >= X$2, IF($M12<>"", $M12, $K12) < Y$2), MID($I12, SEARCH("★M", $I12)+1, 2), ""), IF(AND($S12>=1, IF($M12<>"", $M12, $K12) >= X$2, IF($M12<>"", $M12, $K12) < Y$2), "완료", "")) | Y12: =IF(ISNUMBER(SEARCH("★M", $I12)), IF(AND(IF($M12<>"", $M12, $K12) >= Y$2, IF($M12<>"", $M12, $K12) < Z$2), MID($I12, SEARCH("★M", $I12)+1, 2), ""), IF(AND($S12>=1, IF($M12<>"", $M12, $K12) >= Y$2, IF($M12<>"", $M12, $K12) < Z$2), "완료", "")) | Z12: =IF(ISNUMBER(SEARCH("★M", $I12)), IF(AND(IF($M12<>"", $M12, $K12) >= Z$2, IF($M12<>"", $M12, $K12) < AA$2), MID($I12, SEARCH("★M", $I12)+1, 2), ""), IF(AND($S12>=1, IF($M12<>"", $M12, $K12) >= Z$2, IF($M12<>"", $M12, $K12) < AA$2), "완료", "")) | AA12: =IF(ISNUMBER(SEARCH("★M", $I12)), IF(AND(IF($M12<>"", $M12, $K12) >= AA$2, IF($M12<>"", $M12, $K12) < AB$2), MID($I12, SEARCH("★M", $I12)+1, 2), ""), IF(AND($S12>=1, IF($M12<>"", $M12, $K12) >= AA$2, IF($M12<>"", $M12, $K12) < AB$2), "완료", "")) | AB12: =IF(ISNUMBER(SEARCH("★M", $I12)), IF(AND(IF($M12<>"", $M12, $K12) >= AB$2, IF($M12<>"", $M12, $K12) < AC$2), MID($I12, SEARCH("★M", $I12)+1, 2), ""), IF(AND($S12>=1, IF($M12<>"", $M12, $K12) >= AB$2, IF($M12<>"", $M12, $K12) < AC$2), "완료", "")) | AC12: =IF(ISNUMBER(SEARCH("★M", $I12)), IF(AND(IF($M12<>"", $M12, $K12) >= AC$2, IF($M12<>"", $M12, $K12) < AD$2), MID($I12, SEARCH("★M", $I12)+1, 2), ""), IF(AND($S12>=1, IF($M12<>"", $M12, $K12) >= AC$2, IF($M12<>"", $M12, $K12) < AD$2), "완료", "")) | ... BB12: =IF(ISNUMBER(SEARCH("★M", $I12)), IF(AND(IF($M12<>"", $M12, $K12) >= BB$2, IF($M12<>"", $M12, $K12) < BC$2), MID($I12, SEARCH("★M", $I12)+1, 2), ""), IF(AND($S12>=1, IF($M12<>"", $M12, $K12) >= BB$2, IF($M12<>"", $M12, $K12) < BC$2), "완료", ""))
F13: 3단계 판정 안전망(판정 하향 금지·법령 원문 제시) 아키텍처 정의 | H13: AI 아키텍트 | I13: 시스템아키텍처정의서, 기업용 LLM 비학습 보안정의 | J13: 46335 | K13: 46346 | N13: =IF(OR(ISBLANK(J13),ISBLANK(K13)),"",NETWORKDAYS(J13,K13,'휴일'!$A$2:$A$13)) -> 10 | O13: =IF(OR(ISBLANK(L13),ISBLANK(M13)),"",IF(NETWORKDAYS(L13,M13,'휴일'!$A$2:$A$13)<0,"",NETWORKDAYS(L13,M13,'휴일'!$A$2:$A$13))) | P13: =IFERROR(IF(K13>=$K$1,IF(NETWORKDAYS(J13,$K$1,'휴일'!$A$2:$A$13)>0,NETWORKDAYS(J13,$K$1,'휴일'!$A$2:$A$13),""),NETWORKDAYS(J13,K13,'휴일'!$A$2:$A$13)),"") | Q13: =IF(IFERROR(IF(M13>=$K$1,IF(NETWORKDAYS(L13,$K$1,'휴일'!$A$2:$A$13)>0,NETWORKDAYS(L13,$K$1,'휴일'!$A$2:$A$13),""),NETWORKDAYS(L13,M13,'휴일'!$A$2:$A$13)),"")<0,"",IFERROR(IF(M13>=$K$1,IF(NETWORKDAYS(L13,$K$1,'휴일'!$A$2:$A$13)>0,NETWORKDAYS(L13,$K$1,'휴일'!$A$2:$A$13),""),NETWORKDAYS(L13,M13,'휴일'!$A$2:$A$13)),"")) -> 0 | R13: =IFERROR(P13/N13,0) -> 0 | S13: =IFERROR(Q13/O13,0) -> 0 | T13: =IF(OR(ISBLANK(Q13),ISBLANK(N13),Q13<=0,N13<=0),0,IF(Q13="",0,1-(Q13-N13)/N13)) -> 0 | U13: =T13-R13 -> 0 | V13: =IF(ISNUMBER(SEARCH("★M", $I13)), IF(AND(IF($M13<>"", $M13, $K13) >= V$2, IF($M13<>"", $M13, $K13) < W$2), MID($I13, SEARCH("★M", $I13)+1, 2), ""), IF(AND($S13>=1, IF($M13<>"", $M13, $K13) >= V$2, IF($M13<>"", $M13, $K13) < W$2), "완료", "")) | W13: =IF(ISNUMBER(SEARCH("★M", $I13)), IF(AND(IF($M13<>"", $M13, $K13) >= W$2, IF($M13<>"", $M13, $K13) < X$2), MID($I13, SEARCH("★M", $I13)+1, 2), ""), IF(AND($S13>=1, IF($M13<>"", $M13, $K13) >= W$2, IF($M13<>"", $M13, $K13) < X$2), "완료", "")) | X13: =IF(ISNUMBER(SEARCH("★M", $I13)), IF(AND(IF($M13<>"", $M13, $K13) >= X$2, IF($M13<>"", $M13, $K13) < Y$2), MID($I13, SEARCH("★M", $I13)+1, 2), ""), IF(AND($S13>=1, IF($M13<>"", $M13, $K13) >= X$2, IF($M13<>"", $M13, $K13) < Y$2), "완료", "")) | Y13: =IF(ISNUMBER(SEARCH("★M", $I13)), IF(AND(IF($M13<>"", $M13, $K13) >= Y$2, IF($M13<>"", $M13, $K13) < Z$2), MID($I13, SEARCH("★M", $I13)+1, 2), ""), IF(AND($S13>=1, IF($M13<>"", $M13, $K13) >= Y$2, IF($M13<>"", $M13, $K13) < Z$2), "완료", "")) | Z13: =IF(ISNUMBER(SEARCH("★M", $I13)), IF(AND(IF($M13<>"", $M13, $K13) >= Z$2, IF($M13<>"", $M13, $K13) < AA$2), MID($I13, SEARCH("★M", $I13)+1, 2), ""), IF(AND($S13>=1, IF($M13<>"", $M13, $K13) >= Z$2, IF($M13<>"", $M13, $K13) < AA$2), "완료", "")) | AA13: =IF(ISNUMBER(SEARCH("★M", $I13)), IF(AND(IF($M13<>"", $M13, $K13) >= AA$2, IF($M13<>"", $M13, $K13) < AB$2), MID($I13, SEARCH("★M", $I13)+1, 2), ""), IF(AND($S13>=1, IF($M13<>"", $M13, $K13) >= AA$2, IF($M13<>"", $M13, $K13) < AB$2), "완료", "")) | AB13: =IF(ISNUMBER(SEARCH("★M", $I13)), IF(AND(IF($M13<>"", $M13, $K13) >= AB$2, IF($M13<>"", $M13, $K13) < AC$2), MID($I13, SEARCH("★M", $I13)+1, 2), ""), IF(AND($S13>=1, IF($M13<>"", $M13, $K13) >= AB$2, IF($M13<>"", $M13, $K13) < AC$2), "완료", "")) | AC13: =IF(ISNUMBER(SEARCH("★M", $I13)), IF(AND(IF($M13<>"", $M13, $K13) >= AC$2, IF($M13<>"", $M13, $K13) < AD$2), MID($I13, SEARCH("★M", $I13)+1, 2), ""), IF(AND($S13>=1, IF($M13<>"", $M13, $K13) >= AC$2, IF($M13<>"", $M13, $K13) < AD$2), "완료", "")) | ... BB13: =IF(ISNUMBER(SEARCH("★M", $I13)), IF(AND(IF($M13<>"", $M13, $K13) >= BB$2, IF($M13<>"", $M13, $K13) < BC$2), MID($I13, SEARCH("★M", $I13)+1, 2), ""), IF(AND($S13>=1, IF($M13<>"", $M13, $K13) >= BB$2, IF($M13<>"", $M13, $K13) < BC$2), "완료", ""))
F14: M1 마일스톤 설계 산출물 승인 (11.20 설계 확정) | H14: 사업총괄(PM) | I14: ★M1 설계승인서 (2026.11.20) | J14: 46342 | K14: 46346 | N14: =IF(OR(ISBLANK(J14),ISBLANK(K14)),"",NETWORKDAYS(J14,K14,'휴일'!$A$2:$A$13)) -> 5 | O14: =IF(OR(ISBLANK(L14),ISBLANK(M14)),"",IF(NETWORKDAYS(L14,M14,'휴일'!$A$2:$A$13)<0,"",NETWORKDAYS(L14,M14,'휴일'!$A$2:$A$13))) | P14: =IFERROR(IF(K14>=$K$1,IF(NETWORKDAYS(J14,$K$1,'휴일'!$A$2:$A$13)>0,NETWORKDAYS(J14,$K$1,'휴일'!$A$2:$A$13),""),NETWORKDAYS(J14,K14,'휴일'!$A$2:$A$13)),"") | Q14: =IF(IFERROR(IF(M14>=$K$1,IF(NETWORKDAYS(L14,$K$1,'휴일'!$A$2:$A$13)>0,NETWORKDAYS(L14,$K$1,'휴일'!$A$2:$A$13),""),NETWORKDAYS(L14,M14,'휴일'!$A$2:$A$13)),"")<0,"",IFERROR(IF(M14>=$K$1,IF(NETWORKDAYS(L14,$K$1,'휴일'!$A$2:$A$13)>0,NETWORKDAYS(L14,$K$1,'휴일'!$A$2:$A$13),""),NETWORKDAYS(L14,M14,'휴일'!$A$2:$A$13)),"")) -> 0 | R14: =IFERROR(P14/N14,0) -> 0 | S14: =IFERROR(Q14/O14,0) -> 0 | T14: =IF(OR(ISBLANK(Q14),ISBLANK(N14),Q14<=0,N14<=0),0,IF(Q14="",0,1-(Q14-N14)/N14)) -> 0 | U14: =T14-R14 -> 0 | V14: =IF(ISNUMBER(SEARCH("★M", $I14)), IF(AND(IF($M14<>"", $M14, $K14) >= V$2, IF($M14<>"", $M14, $K14) < W$2), MID($I14, SEARCH("★M", $I14)+1, 2), ""), IF(AND($S14>=1, IF($M14<>"", $M14, $K14) >= V$2, IF($M14<>"", $M14, $K14) < W$2), "완료", "")) | W14: =IF(ISNUMBER(SEARCH("★M", $I14)), IF(AND(IF($M14<>"", $M14, $K14) >= W$2, IF($M14<>"", $M14, $K14) < X$2), MID($I14, SEARCH("★M", $I14)+1, 2), ""), IF(AND($S14>=1, IF($M14<>"", $M14, $K14) >= W$2, IF($M14<>"", $M14, $K14) < X$2), "완료", "")) | X14: =IF(ISNUMBER(SEARCH("★M", $I14)), IF(AND(IF($M14<>"", $M14, $K14) >= X$2, IF($M14<>"", $M14, $K14) < Y$2), MID($I14, SEARCH("★M", $I14)+1, 2), ""), IF(AND($S14>=1, IF($M14<>"", $M14, $K14) >= X$2, IF($M14<>"", $M14, $K14) < Y$2), "완료", "")) | Y14: =IF(ISNUMBER(SEARCH("★M", $I14)), IF(AND(IF($M14<>"", $M14, $K14) >= Y$2, IF($M14<>"", $M14, $K14) < Z$2), MID($I14, SEARCH("★M", $I14)+1, 2), ""), IF(AND($S14>=1, IF($M14<>"", $M14, $K14) >= Y$2, IF($M14<>"", $M14, $K14) < Z$2), "완료", "")) | Z14: =IF(ISNUMBER(SEARCH("★M", $I14)), IF(AND(IF($M14<>"", $M14, $K14) >= Z$2, IF($M14<>"", $M14, $K14) < AA$2), MID($I14, SEARCH("★M", $I14)+1, 2), ""), IF(AND($S14>=1, IF($M14<>"", $M14, $K14) >= Z$2, IF($M14<>"", $M14, $K14) < AA$2), "완료", "")) | AA14: =IF(ISNUMBER(SEARCH("★M", $I14)), IF(AND(IF($M14<>"", $M14, $K14) >= AA$2, IF($M14<>"", $M14, $K14) < AB$2), MID($I14, SEARCH("★M", $I14)+1, 2), ""), IF(AND($S14>=1, IF($M14<>"", $M14, $K14) >= AA$2, IF($M14<>"", $M14, $K14) < AB$2), "완료", "")) -> M1 | AB14: =IF(ISNUMBER(SEARCH("★M", $I14)), IF(AND(IF($M14<>"", $M14, $K14) >= AB$2, IF($M14<>"", $M14, $K14) < AC$2), MID($I14, SEARCH("★M", $I14)+1, 2), ""), IF(AND($S14>=1, IF($M14<>"", $M14, $K14) >= AB$2, IF($M14<>"", $M14, $K14) < AC$2), "완료", "")) | AC14: =IF(ISNUMBER(SEARCH("★M", $I14)), IF(AND(IF($M14<>"", $M14, $K14) >= AC$2, IF($M14<>"", $M14, $K14) < AD$2), MID($I14, SEARCH("★M", $I14)+1, 2), ""), IF(AND($S14>=1, IF($M14<>"", $M14, $K14) >= AC$2, IF($M14<>"", $M14, $K14) < AD$2), "완료", "")) | ... BB14: =IF(ISNUMBER(SEARCH("★M", $I14)), IF(AND(IF($M14<>"", $M14, $K14) >= BB$2, IF($M14<>"", $M14, $K14) < BC$2), MID($I14, SEARCH("★M", $I14)+1, 2), ""), IF(AND($S14>=1, IF($M14<>"", $M14, $K14) >= BB$2, IF($M14<>"", $M14, $K14) < BC$2), "완료", ""))
B15: 3 | C15: 0.4 | D15: 구현 및 AI 엔진 개발 | E15: [03] 규칙 사전·근거 검색·Agent 구축 | F15: 식약처 표시·광고 공정화법·가이드라인 규제 문서 청킹 및 pgvector 적재 | H15: AI 엔지니어 | I15: 규제문서 수집목록, pgvector 임베딩 DB | J15: 46349 | K15: 46374 | N15: =IF(OR(ISBLANK(J15),ISBLANK(K15)),"",NETWORKDAYS(J15,K15,'휴일'!$A$2:$A$13)) -> 20 | O15: =IF(OR(ISBLANK(L15),ISBLANK(M15)),"",IF(NETWORKDAYS(L15,M15,'휴일'!$A$2:$A$13)<0,"",NETWORKDAYS(L15,M15,'휴일'!$A$2:$A$13))) | P15: =IFERROR(IF(K15>=$K$1,IF(NETWORKDAYS(J15,$K$1,'휴일'!$A$2:$A$13)>0,NETWORKDAYS(J15,$K$1,'휴일'!$A$2:$A$13),""),NETWORKDAYS(J15,K15,'휴일'!$A$2:$A$13)),"") | Q15: =IF(IFERROR(IF(M15>=$K$1,IF(NETWORKDAYS(L15,$K$1,'휴일'!$A$2:$A$13)>0,NETWORKDAYS(L15,$K$1,'휴일'!$A$2:$A$13),""),NETWORKDAYS(L15,M15,'휴일'!$A$2:$A$13)),"")<0,"",IFERROR(IF(M15>=$K$1,IF(NETWORKDAYS(L15,$K$1,'휴일'!$A$2:$A$13)>0,NETWORKDAYS(L15,$K$1,'휴일'!$A$2:$A$13),""),NETWORKDAYS(L15,M15,'휴일'!$A$2:$A$13)),"")) -> 0 | R15: =IFERROR(P15/N15,0) -> 0 | S15: =IFERROR(Q15/O15,0) -> 0 | T15: =IF(OR(ISBLANK(Q15),ISBLANK(N15),Q15<=0,N15<=0),0,IF(Q15="",0,1-(Q15-N15)/N15)) -> 0 | U15: =T15-R10 -> 0 | V15: =IF(ISNUMBER(SEARCH("★M", $I15)), IF(AND(IF($M15<>"", $M15, $K15) >= V$2, IF($M15<>"", $M15, $K15) < W$2), MID($I15, SEARCH("★M", $I15)+1, 2), ""), IF(AND($S15>=1, IF($M15<>"", $M15, $K15) >= V$2, IF($M15<>"", $M15, $K15) < W$2), "완료", "")) | W15: =IF(ISNUMBER(SEARCH("★M", $I15)), IF(AND(IF($M15<>"", $M15, $K15) >= W$2, IF($M15<>"", $M15, $K15) < X$2), MID($I15, SEARCH("★M", $I15)+1, 2), ""), IF(AND($S15>=1, IF($M15<>"", $M15, $K15) >= W$2, IF($M15<>"", $M15, $K15) < X$2), "완료", "")) | X15: =IF(ISNUMBER(SEARCH("★M", $I15)), IF(AND(IF($M15<>"", $M15, $K15) >= X$2, IF($M15<>"", $M15, $K15) < Y$2), MID($I15, SEARCH("★M", $I15)+1, 2), ""), IF(AND($S15>=1, IF($M15<>"", $M15, $K15) >= X$2, IF($M15<>"", $M15, $K15) < Y$2), "완료", "")) | Y15: =IF(ISNUMBER(SEARCH("★M", $I15)), IF(AND(IF($M15<>"", $M15, $K15) >= Y$2, IF($M15<>"", $M15, $K15) < Z$2), MID($I15, SEARCH("★M", $I15)+1, 2), ""), IF(AND($S15>=1, IF($M15<>"", $M15, $K15) >= Y$2, IF($M15<>"", $M15, $K15) < Z$2), "완료", "")) | Z15: =IF(ISNUMBER(SEARCH("★M", $I15)), IF(AND(IF($M15<>"", $M15, $K15) >= Z$2, IF($M15<>"", $M15, $K15) < AA$2), MID($I15, SEARCH("★M", $I15)+1, 2), ""), IF(AND($S15>=1, IF($M15<>"", $M15, $K15) >= Z$2, IF($M15<>"", $M15, $K15) < AA$2), "완료", "")) | AA15: =IF(ISNUMBER(SEARCH("★M", $I15)), IF(AND(IF($M15<>"", $M15, $K15) >= AA$2, IF($M15<>"", $M15, $K15) < AB$2), MID($I15, SEARCH("★M", $I15)+1, 2), ""), IF(AND($S15>=1, IF($M15<>"", $M15, $K15) >= AA$2, IF($M15<>"", $M15, $K15) < AB$2), "완료", "")) | AB15: =IF(ISNUMBER(SEARCH("★M", $I15)), IF(AND(IF($M15<>"", $M15, $K15) >= AB$2, IF($M15<>"", $M15, $K15) < AC$2), MID($I15, SEARCH("★M", $I15)+1, 2), ""), IF(AND($S15>=1, IF($M15<>"", $M15, $K15) >= AB$2, IF($M15<>"", $M15, $K15) < AC$2), "완료", "")) | AC15: =IF(ISNUMBER(SEARCH("★M", $I15)), IF(AND(IF($M15<>"", $M15, $K15) >= AC$2, IF($M15<>"", $M15, $K15) < AD$2), MID($I15, SEARCH("★M", $I15)+1, 2), ""), IF(AND($S15>=1, IF($M15<>"", $M15, $K15) >= AC$2, IF($M15<>"", $M15, $K15) < AD$2), "완료", "")) | ... BB15: =IF(ISNUMBER(SEARCH("★M", $I15)), IF(AND(IF($M15<>"", $M15, $K15) >= BB$2, IF($M15<>"", $M15, $K15) < BC$2), MID($I15, SEARCH("★M", $I15)+1, 2), ""), IF(AND($S15>=1, IF($M15<>"", $M15, $K15) >= BB$2, IF($M15<>"", $M15, $K15) < BC$2), "완료", ""))
F16: 사내 심의 기준(질문/답변 분리 엑셀) 기반 표현 사전(100대 규칙) 개발 | H16: AI 엔지니어 | I16: 표현사전(금지/주의/안전) 100대 룰 엔진 | J16: 46356 | K16: 46381 | N16: =IF(OR(ISBLANK(J16),ISBLANK(K16)),"",NETWORKDAYS(J16,K16,'휴일'!$A$2:$A$13)) -> 19 | O16: =IF(OR(ISBLANK(L16),ISBLANK(M16)),"",IF(NETWORKDAYS(L16,M16,'휴일'!$A$2:$A$13)<0,"",NETWORKDAYS(L16,M16,'휴일'!$A$2:$A$13))) | P16: =IFERROR(IF(K16>=$K$1,IF(NETWORKDAYS(J16,$K$1,'휴일'!$A$2:$A$13)>0,NETWORKDAYS(J16,$K$1,'휴일'!$A$2:$A$13),""),NETWORKDAYS(J16,K16,'휴일'!$A$2:$A$13)),"") | Q16: =IF(IFERROR(IF(M16>=$K$1,IF(NETWORKDAYS(L16,$K$1,'휴일'!$A$2:$A$13)>0,NETWORKDAYS(L16,$K$1,'휴일'!$A$2:$A$13),""),NETWORKDAYS(L16,M16,'휴일'!$A$2:$A$13)),"")<0,"",IFERROR(IF(M16>=$K$1,IF(NETWORKDAYS(L16,$K$1,'휴일'!$A$2:$A$13)>0,NETWORKDAYS(L16,$K$1,'휴일'!$A$2:$A$13),""),NETWORKDAYS(L16,M16,'휴일'!$A$2:$A$13)),"")) -> 0 | R16: =IFERROR(P16/N16,0) -> 0 | S16: =IFERROR(Q16/O16,0) -> 0 | T16: =IF(OR(ISBLANK(Q16),ISBLANK(N16),Q16<=0,N16<=0),0,IF(Q16="",0,1-(Q16-N16)/N16)) -> 0 | U16: =T16-R16 -> 0 | V16: =IF(ISNUMBER(SEARCH("★M", $I16)), IF(AND(IF($M16<>"", $M16, $K16) >= V$2, IF($M16<>"", $M16, $K16) < W$2), MID($I16, SEARCH("★M", $I16)+1, 2), ""), IF(AND($S16>=1, IF($M16<>"", $M16, $K16) >= V$2, IF($M16<>"", $M16, $K16) < W$2), "완료", "")) | W16: =IF(ISNUMBER(SEARCH("★M", $I16)), IF(AND(IF($M16<>"", $M16, $K16) >= W$2, IF($M16<>"", $M16, $K16) < X$2), MID($I16, SEARCH("★M", $I16)+1, 2), ""), IF(AND($S16>=1, IF($M16<>"", $M16, $K16) >= W$2, IF($M16<>"", $M16, $K16) < X$2), "완료", "")) | X16: =IF(ISNUMBER(SEARCH("★M", $I16)), IF(AND(IF($M16<>"", $M16, $K16) >= X$2, IF($M16<>"", $M16, $K16) < Y$2), MID($I16, SEARCH("★M", $I16)+1, 2), ""), IF(AND($S16>=1, IF($M16<>"", $M16, $K16) >= X$2, IF($M16<>"", $M16, $K16) < Y$2), "완료", "")) | Y16: =IF(ISNUMBER(SEARCH("★M", $I16)), IF(AND(IF($M16<>"", $M16, $K16) >= Y$2, IF($M16<>"", $M16, $K16) < Z$2), MID($I16, SEARCH("★M", $I16)+1, 2), ""), IF(AND($S16>=1, IF($M16<>"", $M16, $K16) >= Y$2, IF($M16<>"", $M16, $K16) < Z$2), "완료", "")) | Z16: =IF(ISNUMBER(SEARCH("★M", $I16)), IF(AND(IF($M16<>"", $M16, $K16) >= Z$2, IF($M16<>"", $M16, $K16) < AA$2), MID($I16, SEARCH("★M", $I16)+1, 2), ""), IF(AND($S16>=1, IF($M16<>"", $M16, $K16) >= Z$2, IF($M16<>"", $M16, $K16) < AA$2), "완료", "")) | AA16: =IF(ISNUMBER(SEARCH("★M", $I16)), IF(AND(IF($M16<>"", $M16, $K16) >= AA$2, IF($M16<>"", $M16, $K16) < AB$2), MID($I16, SEARCH("★M", $I16)+1, 2), ""), IF(AND($S16>=1, IF($M16<>"", $M16, $K16) >= AA$2, IF($M16<>"", $M16, $K16) < AB$2), "완료", "")) | AB16: =IF(ISNUMBER(SEARCH("★M", $I16)), IF(AND(IF($M16<>"", $M16, $K16) >= AB$2, IF($M16<>"", $M16, $K16) < AC$2), MID($I16, SEARCH("★M", $I16)+1, 2), ""), IF(AND($S16>=1, IF($M16<>"", $M16, $K16) >= AB$2, IF($M16<>"", $M16, $K16) < AC$2), "완료", "")) | AC16: =IF(ISNUMBER(SEARCH("★M", $I16)), IF(AND(IF($M16<>"", $M16, $K16) >= AC$2, IF($M16<>"", $M16, $K16) < AD$2), MID($I16, SEARCH("★M", $I16)+1, 2), ""), IF(AND($S16>=1, IF($M16<>"", $M16, $K16) >= AC$2, IF($M16<>"", $M16, $K16) < AD$2), "완료", "")) | ... BB16: =IF(ISNUMBER(SEARCH("★M", $I16)), IF(AND(IF($M16<>"", $M16, $K16) >= BB$2, IF($M16<>"", $M16, $K16) < BC$2), MID($I16, SEARCH("★M", $I16)+1, 2), ""), IF(AND($S16>=1, IF($M16<>"", $M16, $K16) >= BB$2, IF($M16<>"", $M16, $K16) < BC$2), "완료", ""))
F17: 하이브리드 RAG 법령·사례 검색 및 근거 원문 추출 Agent 구축 | H17: AI 아키텍트 | I17: RAG 검색엔진 및 법적 근거 원문 제시 모듈 | J17: 46370 | K17: 46402 | N17: =IF(OR(ISBLANK(J17),ISBLANK(K17)),"",NETWORKDAYS(J17,K17,'휴일'!$A$2:$A$13)) -> 23 | O17: =IF(OR(ISBLANK(L17),ISBLANK(M17)),"",IF(NETWORKDAYS(L17,M17,'휴일'!$A$2:$A$13)<0,"",NETWORKDAYS(L17,M17,'휴일'!$A$2:$A$13))) | P17: =IFERROR(IF(K17>=$K$1,IF(NETWORKDAYS(J17,$K$1,'휴일'!$A$2:$A$13)>0,NETWORKDAYS(J17,$K$1,'휴일'!$A$2:$A$13),""),NETWORKDAYS(J17,K17,'휴일'!$A$2:$A$13)),"") | Q17: =IF(IFERROR(IF(M17>=$K$1,IF(NETWORKDAYS(L17,$K$1,'휴일'!$A$2:$A$13)>0,NETWORKDAYS(L17,$K$1,'휴일'!$A$2:$A$13),""),NETWORKDAYS(L17,M17,'휴일'!$A$2:$A$13)),"")<0,"",IFERROR(IF(M17>=$K$1,IF(NETWORKDAYS(L17,$K$1,'휴일'!$A$2:$A$13)>0,NETWORKDAYS(L17,$K$1,'휴일'!$A$2:$A$13),""),NETWORKDAYS(L17,M17,'휴일'!$A$2:$A$13)),"")) -> 0 | R17: =IFERROR(P17/N17,0) -> 0 | S17: =IFERROR(Q17/O17,0) -> 0 | T17: =IF(OR(ISBLANK(Q17),ISBLANK(N17),Q17<=0,N17<=0),0,IF(Q17="",0,1-(Q17-N17)/N17)) -> 0 | U17: =T17-R17 -> 0 | V17: =IF(ISNUMBER(SEARCH("★M", $I17)), IF(AND(IF($M17<>"", $M17, $K17) >= V$2, IF($M17<>"", $M17, $K17) < W$2), MID($I17, SEARCH("★M", $I17)+1, 2), ""), IF(AND($S17>=1, IF($M17<>"", $M17, $K17) >= V$2, IF($M17<>"", $M17, $K17) < W$2), "완료", "")) | W17: =IF(ISNUMBER(SEARCH("★M", $I17)), IF(AND(IF($M17<>"", $M17, $K17) >= W$2, IF($M17<>"", $M17, $K17) < X$2), MID($I17, SEARCH("★M", $I17)+1, 2), ""), IF(AND($S17>=1, IF($M17<>"", $M17, $K17) >= W$2, IF($M17<>"", $M17, $K17) < X$2), "완료", "")) | X17: =IF(ISNUMBER(SEARCH("★M", $I17)), IF(AND(IF($M17<>"", $M17, $K17) >= X$2, IF($M17<>"", $M17, $K17) < Y$2), MID($I17, SEARCH("★M", $I17)+1, 2), ""), IF(AND($S17>=1, IF($M17<>"", $M17, $K17) >= X$2, IF($M17<>"", $M17, $K17) < Y$2), "완료", "")) | Y17: =IF(ISNUMBER(SEARCH("★M", $I17)), IF(AND(IF($M17<>"", $M17, $K17) >= Y$2, IF($M17<>"", $M17, $K17) < Z$2), MID($I17, SEARCH("★M", $I17)+1, 2), ""), IF(AND($S17>=1, IF($M17<>"", $M17, $K17) >= Y$2, IF($M17<>"", $M17, $K17) < Z$2), "완료", "")) | Z17: =IF(ISNUMBER(SEARCH("★M", $I17)), IF(AND(IF($M17<>"", $M17, $K17) >= Z$2, IF($M17<>"", $M17, $K17) < AA$2), MID($I17, SEARCH("★M", $I17)+1, 2), ""), IF(AND($S17>=1, IF($M17<>"", $M17, $K17) >= Z$2, IF($M17<>"", $M17, $K17) < AA$2), "완료", "")) | AA17: =IF(ISNUMBER(SEARCH("★M", $I17)), IF(AND(IF($M17<>"", $M17, $K17) >= AA$2, IF($M17<>"", $M17, $K17) < AB$2), MID($I17, SEARCH("★M", $I17)+1, 2), ""), IF(AND($S17>=1, IF($M17<>"", $M17, $K17) >= AA$2, IF($M17<>"", $M17, $K17) < AB$2), "완료", "")) | AB17: =IF(ISNUMBER(SEARCH("★M", $I17)), IF(AND(IF($M17<>"", $M17, $K17) >= AB$2, IF($M17<>"", $M17, $K17) < AC$2), MID($I17, SEARCH("★M", $I17)+1, 2), ""), IF(AND($S17>=1, IF($M17<>"", $M17, $K17) >= AB$2, IF($M17<>"", $M17, $K17) < AC$2), "완료", "")) | AC17: =IF(ISNUMBER(SEARCH("★M", $I17)), IF(AND(IF($M17<>"", $M17, $K17) >= AC$2, IF($M17<>"", $M17, $K17) < AD$2), MID($I17, SEARCH("★M", $I17)+1, 2), ""), IF(AND($S17>=1, IF($M17<>"", $M17, $K17) >= AC$2, IF($M17<>"", $M17, $K17) < AD$2), "완료", "")) | ... BB17: =IF(ISNUMBER(SEARCH("★M", $I17)), IF(AND(IF($M17<>"", $M17, $K17) >= BB$2, IF($M17<>"", $M17, $K17) < BC$2), MID($I17, SEARCH("★M", $I17)+1, 2), ""), IF(AND($S17>=1, IF($M17<>"", $M17, $K17) >= BB$2, IF($M17<>"", $M17, $K17) < BC$2), "완료", ""))
E18: [04] 3단계 판정 엔진·프롬프트 개발 (M2) | F18: PDF/PPT/JPG/동영상(지정 캡처 장면) 파싱 및 3단계 판정·대체문구 개발 | H18: AI 엔지니어 | I18: ★M2 중간보고 프로토타입 (국·영문 번역심의 포함) | J18: 46363 | K18: 46416 | N18: =IF(OR(ISBLANK(J18),ISBLANK(K18)),"",NETWORKDAYS(J18,K18,'휴일'!$A$2:$A$13)) -> 38 | O18: =IF(OR(ISBLANK(L18),ISBLANK(M18)),"",IF(NETWORKDAYS(L18,M18,'휴일'!$A$2:$A$13)<0,"",NETWORKDAYS(L18,M18,'휴일'!$A$2:$A$13))) | P18: =IFERROR(IF(K18>=$K$1,IF(NETWORKDAYS(J18,$K$1,'휴일'!$A$2:$A$13)>0,NETWORKDAYS(J18,$K$1,'휴일'!$A$2:$A$13),""),NETWORKDAYS(J18,K18,'휴일'!$A$2:$A$13)),"") | Q18: =IF(IFERROR(IF(M18>=$K$1,IF(NETWORKDAYS(L18,$K$1,'휴일'!$A$2:$A$13)>0,NETWORKDAYS(L18,$K$1,'휴일'!$A$2:$A$13),""),NETWORKDAYS(L18,M18,'휴일'!$A$2:$A$13)),"")<0,"",IFERROR(IF(M18>=$K$1,IF(NETWORKDAYS(L18,$K$1,'휴일'!$A$2:$A$13)>0,NETWORKDAYS(L18,$K$1,'휴일'!$A$2:$A$13),""),NETWORKDAYS(L18,M18,'휴일'!$A$2:$A$13)),"")) -> 0 | R18: =IFERROR(P18/N18,0) -> 0 | S18: =IFERROR(Q18/O18,0) -> 0 | T18: =IF(OR(ISBLANK(Q18),ISBLANK(N18),Q18<=0,N18<=0),0,IF(Q18="",0,1-(Q18-N18)/N18)) -> 0 | U18: =T18-R18 -> 0 | V18: =IF(ISNUMBER(SEARCH("★M", $I18)), IF(AND(IF($M18<>"", $M18, $K18) >= V$2, IF($M18<>"", $M18, $K18) < W$2), MID($I18, SEARCH("★M", $I18)+1, 2), ""), IF(AND($S18>=1, IF($M18<>"", $M18, $K18) >= V$2, IF($M18<>"", $M18, $K18) < W$2), "완료", "")) | W18: =IF(ISNUMBER(SEARCH("★M", $I18)), IF(AND(IF($M18<>"", $M18, $K18) >= W$2, IF($M18<>"", $M18, $K18) < X$2), MID($I18, SEARCH("★M", $I18)+1, 2), ""), IF(AND($S18>=1, IF($M18<>"", $M18, $K18) >= W$2, IF($M18<>"", $M18, $K18) < X$2), "완료", "")) | X18: =IF(ISNUMBER(SEARCH("★M", $I18)), IF(AND(IF($M18<>"", $M18, $K18) >= X$2, IF($M18<>"", $M18, $K18) < Y$2), MID($I18, SEARCH("★M", $I18)+1, 2), ""), IF(AND($S18>=1, IF($M18<>"", $M18, $K18) >= X$2, IF($M18<>"", $M18, $K18) < Y$2), "완료", "")) | Y18: =IF(ISNUMBER(SEARCH("★M", $I18)), IF(AND(IF($M18<>"", $M18, $K18) >= Y$2, IF($M18<>"", $M18, $K18) < Z$2), MID($I18, SEARCH("★M", $I18)+1, 2), ""), IF(AND($S18>=1, IF($M18<>"", $M18, $K18) >= Y$2, IF($M18<>"", $M18, $K18) < Z$2), "완료", "")) | Z18: =IF(ISNUMBER(SEARCH("★M", $I18)), IF(AND(IF($M18<>"", $M18, $K18) >= Z$2, IF($M18<>"", $M18, $K18) < AA$2), MID($I18, SEARCH("★M", $I18)+1, 2), ""), IF(AND($S18>=1, IF($M18<>"", $M18, $K18) >= Z$2, IF($M18<>"", $M18, $K18) < AA$2), "완료", "")) | AA18: =IF(ISNUMBER(SEARCH("★M", $I18)), IF(AND(IF($M18<>"", $M18, $K18) >= AA$2, IF($M18<>"", $M18, $K18) < AB$2), MID($I18, SEARCH("★M", $I18)+1, 2), ""), IF(AND($S18>=1, IF($M18<>"", $M18, $K18) >= AA$2, IF($M18<>"", $M18, $K18) < AB$2), "완료", "")) | AB18: =IF(ISNUMBER(SEARCH("★M", $I18)), IF(AND(IF($M18<>"", $M18, $K18) >= AB$2, IF($M18<>"", $M18, $K18) < AC$2), MID($I18, SEARCH("★M", $I18)+1, 2), ""), IF(AND($S18>=1, IF($M18<>"", $M18, $K18) >= AB$2, IF($M18<>"", $M18, $K18) < AC$2), "완료", "")) | AC18: =IF(ISNUMBER(SEARCH("★M", $I18)), IF(AND(IF($M18<>"", $M18, $K18) >= AC$2, IF($M18<>"", $M18, $K18) < AD$2), MID($I18, SEARCH("★M", $I18)+1, 2), ""), IF(AND($S18>=1, IF($M18<>"", $M18, $K18) >= AC$2, IF($M18<>"", $M18, $K18) < AD$2), "완료", "")) | ... BB18: =IF(ISNUMBER(SEARCH("★M", $I18)), IF(AND(IF($M18<>"", $M18, $K18) >= BB$2, IF($M18<>"", $M18, $K18) < BC$2), MID($I18, SEARCH("★M", $I18)+1, 2), ""), IF(AND($S18>=1, IF($M18<>"", $M18, $K18) >= BB$2, IF($M18<>"", $M18, $K18) < BC$2), "완료", ""))
F19: 판정 하향 금지 가드레일 및 법적 근거 부재 시 판정 유보 안전망 개발 | H19: AI 아키텍트 | I19: 판정 하향 금지 및 실증 필요 여부 분석 모듈 | J19: 46377 | K19: 46416 | N19: =IF(OR(ISBLANK(J19),ISBLANK(K19)),"",NETWORKDAYS(J19,K19,'휴일'!$A$2:$A$13)) -> 28 | O19: =IF(OR(ISBLANK(L19),ISBLANK(M19)),"",IF(NETWORKDAYS(L19,M19,'휴일'!$A$2:$A$13)<0,"",NETWORKDAYS(L19,M19,'휴일'!$A$2:$A$13))) | P19: =IFERROR(IF(K19>=$K$1,IF(NETWORKDAYS(J19,$K$1,'휴일'!$A$2:$A$13)>0,NETWORKDAYS(J19,$K$1,'휴일'!$A$2:$A$13),""),NETWORKDAYS(J19,K19,'휴일'!$A$2:$A$13)),"") | Q19: =IF(IFERROR(IF(M19>=$K$1,IF(NETWORKDAYS(L19,$K$1,'휴일'!$A$2:$A$13)>0,NETWORKDAYS(L19,$K$1,'휴일'!$A$2:$A$13),""),NETWORKDAYS(L19,M19,'휴일'!$A$2:$A$13)),"")<0,"",IFERROR(IF(M19>=$K$1,IF(NETWORKDAYS(L19,$K$1,'휴일'!$A$2:$A$13)>0,NETWORKDAYS(L19,$K$1,'휴일'!$A$2:$A$13),""),NETWORKDAYS(L19,M19,'휴일'!$A$2:$A$13)),"")) -> 0 | R19: =IFERROR(P19/N19,0) -> 0 | S19: =IFERROR(Q19/O19,0) -> 0 | T19: =IF(OR(ISBLANK(Q19),ISBLANK(N19),Q19<=0,N19<=0),0,IF(Q19="",0,1-(Q19-N19)/N19)) -> 0 | U19: =T19-R19 -> 0 | V19: =IF(ISNUMBER(SEARCH("★M", $I19)), IF(AND(IF($M19<>"", $M19, $K19) >= V$2, IF($M19<>"", $M19, $K19) < W$2), MID($I19, SEARCH("★M", $I19)+1, 2), ""), IF(AND($S19>=1, IF($M19<>"", $M19, $K19) >= V$2, IF($M19<>"", $M19, $K19) < W$2), "완료", "")) | W19: =IF(ISNUMBER(SEARCH("★M", $I19)), IF(AND(IF($M19<>"", $M19, $K19) >= W$2, IF($M19<>"", $M19, $K19) < X$2), MID($I19, SEARCH("★M", $I19)+1, 2), ""), IF(AND($S19>=1, IF($M19<>"", $M19, $K19) >= W$2, IF($M19<>"", $M19, $K19) < X$2), "완료", "")) | X19: =IF(ISNUMBER(SEARCH("★M", $I19)), IF(AND(IF($M19<>"", $M19, $K19) >= X$2, IF($M19<>"", $M19, $K19) < Y$2), MID($I19, SEARCH("★M", $I19)+1, 2), ""), IF(AND($S19>=1, IF($M19<>"", $M19, $K19) >= X$2, IF($M19<>"", $M19, $K19) < Y$2), "완료", "")) | Y19: =IF(ISNUMBER(SEARCH("★M", $I19)), IF(AND(IF($M19<>"", $M19, $K19) >= Y$2, IF($M19<>"", $M19, $K19) < Z$2), MID($I19, SEARCH("★M", $I19)+1, 2), ""), IF(AND($S19>=1, IF($M19<>"", $M19, $K19) >= Y$2, IF($M19<>"", $M19, $K19) < Z$2), "완료", "")) | Z19: =IF(ISNUMBER(SEARCH("★M", $I19)), IF(AND(IF($M19<>"", $M19, $K19) >= Z$2, IF($M19<>"", $M19, $K19) < AA$2), MID($I19, SEARCH("★M", $I19)+1, 2), ""), IF(AND($S19>=1, IF($M19<>"", $M19, $K19) >= Z$2, IF($M19<>"", $M19, $K19) < AA$2), "완료", "")) | AA19: =IF(ISNUMBER(SEARCH("★M", $I19)), IF(AND(IF($M19<>"", $M19, $K19) >= AA$2, IF($M19<>"", $M19, $K19) < AB$2), MID($I19, SEARCH("★M", $I19)+1, 2), ""), IF(AND($S19>=1, IF($M19<>"", $M19, $K19) >= AA$2, IF($M19<>"", $M19, $K19) < AB$2), "완료", "")) | AB19: =IF(ISNUMBER(SEARCH("★M", $I19)), IF(AND(IF($M19<>"", $M19, $K19) >= AB$2, IF($M19<>"", $M19, $K19) < AC$2), MID($I19, SEARCH("★M", $I19)+1, 2), ""), IF(AND($S19>=1, IF($M19<>"", $M19, $K19) >= AB$2, IF($M19<>"", $M19, $K19) < AC$2), "완료", "")) | AC19: =IF(ISNUMBER(SEARCH("★M", $I19)), IF(AND(IF($M19<>"", $M19, $K19) >= AC$2, IF($M19<>"", $M19, $K19) < AD$2), MID($I19, SEARCH("★M", $I19)+1, 2), ""), IF(AND($S19>=1, IF($M19<>"", $M19, $K19) >= AC$2, IF($M19<>"", $M19, $K19) < AD$2), "완료", "")) | ... BB19: =IF(ISNUMBER(SEARCH("★M", $I19)), IF(AND(IF($M19<>"", $M19, $K19) >= BB$2, IF($M19<>"", $M19, $K19) < BC$2), MID($I19, SEARCH("★M", $I19)+1, 2), ""), IF(AND($S19>=1, IF($M19<>"", $M19, $K19) >= BB$2, IF($M19<>"", $M19, $K19) < BC$2), "완료", ""))
E20: [05] 대조 뷰어·관리자 화면 및 결과 파일 고도화 | F20: Side-by-Side 시안 대조 뷰어(장면 이미지·문구 번호 클릭 연동) 개발 | H20: 프론트엔드 개발자 | I20: 시안 대조 뷰어 및 동영상 장면 캡처 워크벤치 | J20: 46384 | K20: 46430 | N20: =IF(OR(ISBLANK(J20),ISBLANK(K20)),"",NETWORKDAYS(J20,K20,'휴일'!$A$2:$A$13)) -> 32 | O20: =IF(OR(ISBLANK(L20),ISBLANK(M20)),"",IF(NETWORKDAYS(L20,M20,'휴일'!$A$2:$A$13)<0,"",NETWORKDAYS(L20,M20,'휴일'!$A$2:$A$13))) | P20: =IFERROR(IF(K20>=$K$1,IF(NETWORKDAYS(J20,$K$1,'휴일'!$A$2:$A$13)>0,NETWORKDAYS(J20,$K$1,'휴일'!$A$2:$A$13),""),NETWORKDAYS(J20,K20,'휴일'!$A$2:$A$13)),"") | Q20: =IF(IFERROR(IF(M20>=$K$1,IF(NETWORKDAYS(L20,$K$1,'휴일'!$A$2:$A$13)>0,NETWORKDAYS(L20,$K$1,'휴일'!$A$2:$A$13),""),NETWORKDAYS(L20,M20,'휴일'!$A$2:$A$13)),"")<0,"",IFERROR(IF(M20>=$K$1,IF(NETWORKDAYS(L20,$K$1,'휴일'!$A$2:$A$13)>0,NETWORKDAYS(L20,$K$1,'휴일'!$A$2:$A$13),""),NETWORKDAYS(L20,M20,'휴일'!$A$2:$A$13)),"")) -> 0 | R20: =IFERROR(P20/N20,0) -> 0 | S20: =IFERROR(Q20/O20,0) -> 0 | T20: =IF(OR(ISBLANK(Q20),ISBLANK(N20),Q20<=0,N20<=0),0,IF(Q20="",0,1-(Q20-N20)/N20)) -> 0 | U20: =T20-R20 -> 0 | V20: =IF(ISNUMBER(SEARCH("★M", $I20)), IF(AND(IF($M20<>"", $M20, $K20) >= V$2, IF($M20<>"", $M20, $K20) < W$2), MID($I20, SEARCH("★M", $I20)+1, 2), ""), IF(AND($S20>=1, IF($M20<>"", $M20, $K20) >= V$2, IF($M20<>"", $M20, $K20) < W$2), "완료", "")) | W20: =IF(ISNUMBER(SEARCH("★M", $I20)), IF(AND(IF($M20<>"", $M20, $K20) >= W$2, IF($M20<>"", $M20, $K20) < X$2), MID($I20, SEARCH("★M", $I20)+1, 2), ""), IF(AND($S20>=1, IF($M20<>"", $M20, $K20) >= W$2, IF($M20<>"", $M20, $K20) < X$2), "완료", "")) | X20: =IF(ISNUMBER(SEARCH("★M", $I20)), IF(AND(IF($M20<>"", $M20, $K20) >= X$2, IF($M20<>"", $M20, $K20) < Y$2), MID($I20, SEARCH("★M", $I20)+1, 2), ""), IF(AND($S20>=1, IF($M20<>"", $M20, $K20) >= X$2, IF($M20<>"", $M20, $K20) < Y$2), "완료", "")) | Y20: =IF(ISNUMBER(SEARCH("★M", $I20)), IF(AND(IF($M20<>"", $M20, $K20) >= Y$2, IF($M20<>"", $M20, $K20) < Z$2), MID($I20, SEARCH("★M", $I20)+1, 2), ""), IF(AND($S20>=1, IF($M20<>"", $M20, $K20) >= Y$2, IF($M20<>"", $M20, $K20) < Z$2), "완료", "")) | Z20: =IF(ISNUMBER(SEARCH("★M", $I20)), IF(AND(IF($M20<>"", $M20, $K20) >= Z$2, IF($M20<>"", $M20, $K20) < AA$2), MID($I20, SEARCH("★M", $I20)+1, 2), ""), IF(AND($S20>=1, IF($M20<>"", $M20, $K20) >= Z$2, IF($M20<>"", $M20, $K20) < AA$2), "완료", "")) | AA20: =IF(ISNUMBER(SEARCH("★M", $I20)), IF(AND(IF($M20<>"", $M20, $K20) >= AA$2, IF($M20<>"", $M20, $K20) < AB$2), MID($I20, SEARCH("★M", $I20)+1, 2), ""), IF(AND($S20>=1, IF($M20<>"", $M20, $K20) >= AA$2, IF($M20<>"", $M20, $K20) < AB$2), "완료", "")) | AB20: =IF(ISNUMBER(SEARCH("★M", $I20)), IF(AND(IF($M20<>"", $M20, $K20) >= AB$2, IF($M20<>"", $M20, $K20) < AC$2), MID($I20, SEARCH("★M", $I20)+1, 2), ""), IF(AND($S20>=1, IF($M20<>"", $M20, $K20) >= AB$2, IF($M20<>"", $M20, $K20) < AC$2), "완료", "")) | AC20: =IF(ISNUMBER(SEARCH("★M", $I20)), IF(AND(IF($M20<>"", $M20, $K20) >= AC$2, IF($M20<>"", $M20, $K20) < AD$2), MID($I20, SEARCH("★M", $I20)+1, 2), ""), IF(AND($S20>=1, IF($M20<>"", $M20, $K20) >= AC$2, IF($M20<>"", $M20, $K20) < AD$2), "완료", "")) | ... BB20: =IF(ISNUMBER(SEARCH("★M", $I20)), IF(AND(IF($M20<>"", $M20, $K20) >= BB$2, IF($M20<>"", $M20, $K20) < BC$2), MID($I20, SEARCH("★M", $I20)+1, 2), ""), IF(AND($S20>=1, IF($M20<>"", $M20, $K20) >= BB$2, IF($M20<>"", $M20, $K20) < BC$2), "완료", ""))
F21: RA 최종 판정(반영/확정) 피드백 UI 및 표현사전·규제문서 관리자 웹 개발 | H21: 프론트엔드 개발자 | I21: RA 관리자 사이트(표현사전·규제문서 버전관리) | J21: 46398 | K21: 46437 | N21: =IF(OR(ISBLANK(J21),ISBLANK(K21)),"",NETWORKDAYS(J21,K21,'휴일'!$A$2:$A$13)) -> 28 | O21: =IF(OR(ISBLANK(L21),ISBLANK(M21)),"",IF(NETWORKDAYS(L21,M21,'휴일'!$A$2:$A$13)<0,"",NETWORKDAYS(L21,M21,'휴일'!$A$2:$A$13))) | P21: =IFERROR(IF(K21>=$K$1,IF(NETWORKDAYS(J21,$K$1,'휴일'!$A$2:$A$13)>0,NETWORKDAYS(J21,$K$1,'휴일'!$A$2:$A$13),""),NETWORKDAYS(J21,K21,'휴일'!$A$2:$A$13)),"") | Q21: =IF(IFERROR(IF(M21>=$K$1,IF(NETWORKDAYS(L21,$K$1,'휴일'!$A$2:$A$13)>0,NETWORKDAYS(L21,$K$1,'휴일'!$A$2:$A$13),""),NETWORKDAYS(L21,M21,'휴일'!$A$2:$A$13)),"")<0,"",IFERROR(IF(M21>=$K$1,IF(NETWORKDAYS(L21,$K$1,'휴일'!$A$2:$A$13)>0,NETWORKDAYS(L21,$K$1,'휴일'!$A$2:$A$13),""),NETWORKDAYS(L21,M21,'휴일'!$A$2:$A$13)),"")) -> 0 | R21: =IFERROR(P21/N21,0) -> 0 | S21: =IFERROR(Q21/O21,0) -> 0 | T21: =IF(OR(ISBLANK(Q21),ISBLANK(N21),Q21<=0,N21<=0),0,IF(Q21="",0,1-(Q21-N21)/N21)) -> 0 | U21: =T21-R21 -> 0 | V21: =IF(ISNUMBER(SEARCH("★M", $I21)), IF(AND(IF($M21<>"", $M21, $K21) >= V$2, IF($M21<>"", $M21, $K21) < W$2), MID($I21, SEARCH("★M", $I21)+1, 2), ""), IF(AND($S21>=1, IF($M21<>"", $M21, $K21) >= V$2, IF($M21<>"", $M21, $K21) < W$2), "완료", "")) | W21: =IF(ISNUMBER(SEARCH("★M", $I21)), IF(AND(IF($M21<>"", $M21, $K21) >= W$2, IF($M21<>"", $M21, $K21) < X$2), MID($I21, SEARCH("★M", $I21)+1, 2), ""), IF(AND($S21>=1, IF($M21<>"", $M21, $K21) >= W$2, IF($M21<>"", $M21, $K21) < X$2), "완료", "")) | X21: =IF(ISNUMBER(SEARCH("★M", $I21)), IF(AND(IF($M21<>"", $M21, $K21) >= X$2, IF($M21<>"", $M21, $K21) < Y$2), MID($I21, SEARCH("★M", $I21)+1, 2), ""), IF(AND($S21>=1, IF($M21<>"", $M21, $K21) >= X$2, IF($M21<>"", $M21, $K21) < Y$2), "완료", "")) | Y21: =IF(ISNUMBER(SEARCH("★M", $I21)), IF(AND(IF($M21<>"", $M21, $K21) >= Y$2, IF($M21<>"", $M21, $K21) < Z$2), MID($I21, SEARCH("★M", $I21)+1, 2), ""), IF(AND($S21>=1, IF($M21<>"", $M21, $K21) >= Y$2, IF($M21<>"", $M21, $K21) < Z$2), "완료", "")) | Z21: =IF(ISNUMBER(SEARCH("★M", $I21)), IF(AND(IF($M21<>"", $M21, $K21) >= Z$2, IF($M21<>"", $M21, $K21) < AA$2), MID($I21, SEARCH("★M", $I21)+1, 2), ""), IF(AND($S21>=1, IF($M21<>"", $M21, $K21) >= Z$2, IF($M21<>"", $M21, $K21) < AA$2), "완료", "")) | AA21: =IF(ISNUMBER(SEARCH("★M", $I21)), IF(AND(IF($M21<>"", $M21, $K21) >= AA$2, IF($M21<>"", $M21, $K21) < AB$2), MID($I21, SEARCH("★M", $I21)+1, 2), ""), IF(AND($S21>=1, IF($M21<>"", $M21, $K21) >= AA$2, IF($M21<>"", $M21, $K21) < AB$2), "완료", "")) | AB21: =IF(ISNUMBER(SEARCH("★M", $I21)), IF(AND(IF($M21<>"", $M21, $K21) >= AB$2, IF($M21<>"", $M21, $K21) < AC$2), MID($I21, SEARCH("★M", $I21)+1, 2), ""), IF(AND($S21>=1, IF($M21<>"", $M21, $K21) >= AB$2, IF($M21<>"", $M21, $K21) < AC$2), "완료", "")) | AC21: =IF(ISNUMBER(SEARCH("★M", $I21)), IF(AND(IF($M21<>"", $M21, $K21) >= AC$2, IF($M21<>"", $M21, $K21) < AD$2), MID($I21, SEARCH("★M", $I21)+1, 2), ""), IF(AND($S21>=1, IF($M21<>"", $M21, $K21) >= AC$2, IF($M21<>"", $M21, $K21) < AD$2), "완료", "")) | ... BB21: =IF(ISNUMBER(SEARCH("★M", $I21)), IF(AND(IF($M21<>"", $M21, $K21) >= BB$2, IF($M21<>"", $M21, $K21) < BC$2), MID($I21, SEARCH("★M", $I21)+1, 2), ""), IF(AND($S21>=1, IF($M21<>"", $M21, $K21) >= BB$2, IF($M21<>"", $M21, $K21) < BC$2), "완료", ""))
